<mujoco model="MuJoCo Model">
  <compiler angle="radian" meshdir="asset/" texturedir="asset/"/>

  <option timestep="0.001" tolerance="1e-06" integrator="implicitfast"/>

  <size memory="2000M"/>

  <visual>
    <map stiffness="700" fogstart="1" fogend="15" zfar="40" haze="1" shadowscale="0.5"/>
    <rgba haze="0.15 0.25 0.35 1"/>
  </visual>

  <statistic meansize="0.05"/>

  <asset>
    <texture type="skybox" builtin="gradient" rgb1="0.3 0.5 0.7" rgb2="0 0 0" width="512" height="3072"/>
    <texture type="2d" name="texplane" builtin="checker" mark="cross" rgb1="0.2 0.3 0.4" rgb2="0.1 0.15 0.2" markrgb="0.8 0.8 0.8" width="512" height="512"/>
    <material name="matplane" texture="texplane" texuniform="true" texrepeat="10 10" reflectance="0.3"/>
  </asset>

  <worldbody>
    <geom name="ground" size="0 0 1" pos="0 0 -2" type="plane" condim="1" material="matplane"/>
    <light pos="30 30 20" dir="0 0 -1" diffuse="0.4 0.4 0.4" specular="0.1 0.1 0.1"/>
    <light pos="-20 -20 40" dir="0.0990148 0.0990148 -0.990148" directional="true" diffuse="0.8 0.8 0.8" specular="0.2 0.2 0.2"/>
    <body name="target" pos="-300 3 3.5">
      <geom size="1 1 3" type="box" rgba="1 0 0 0.7"/>
    </body>
    <body name="vsr_0" pos="4 4 4">
      <inertial pos="0 0 0" mass="0.1" diaginertia="1.66667e-06 1.66667e-06 1.66667e-06"/>
      <joint pos="0 0 0" axis="1 0 0" type="slide"/>
      <joint pos="0 0 0" axis="0 1 0" type="slide"/>
      <joint pos="0 0 0" axis="0 0 1" type="slide"/>
    </body>
    <body name="vsr_1" pos="4 4 5">
      <inertial pos="0 0 0" mass="0.1" diaginertia="1.66667e-06 1.66667e-06 1.66667e-06"/>
      <joint pos="0 0 0" axis="1 0 0" type="slide"/>
      <joint pos="0 0 0" axis="0 1 0" type="slide"/>
      <joint pos="0 0 0" axis="0 0 1" type="slide"/>
    </body>
    <body name="vsr_2" pos="4 4 6">
      <inertial pos="0 0 0" mass="0.1" diaginertia="1.66667e-06 1.66667e-06 1.66667e-06"/>
      <joint pos="0 0 0" axis="1 0 0" type="slide"/>
      <joint pos="0 0 0" axis="0 1 0" type="slide"/>
      <joint pos="0 0 0" axis="0 0 1" type="slide"/>
    </body>
    <body name="vsr_3" pos="4 5 4">
      <inertial pos="0 0 0" mass="0.1" diaginertia="1.66667e-06 1.66667e-06 1.66667e-06"/>
      <joint pos="0 0 0" axis="1 0 0" type="slide"/>
      <joint pos="0 0 0" axis="0 1 0" type="slide"/>
      <joint pos="0 0 0" axis="0 0 1" type="slide"/>
    </body>
    <body name="vsr_4" pos="4 5 5">
      <inertial pos="0 0 0" mass="0.1" diaginertia="1.66667e-06 1.66667e-06 1.66667e-06"/>
      <joint pos="0 0 0" axis="1 0 0" type="slide"/>
      <joint pos="0 0 0" axis="0 1 0" type="slide"/>
      <joint pos="0 0 0" axis="0 0 1" type="slide"/>
    </body>
    <body name="vsr_5" pos="4 5 6">
      <inertial pos="0 0 0" mass="0.1" diaginertia="1.66667e-06 1.66667e-06 1.66667e-06"/>
      <joint pos="0 0 0" axis="1 0 0" type="slide"/>
      <joint pos="0 0 0" axis="0 1 0" type="slide"/>
      <joint pos="0 0 0" axis="0 0 1" type="slide"/>
    </body>
    <body name="vsr_6" pos="4 6 4">
      <inertial pos="0 0 0" mass="0.1" diaginertia="1.66667e-06 1.66667e-06 1.66667e-06"/>
      <joint pos="0 0 0" axis="1 0 0" type="slide"/>
      <joint pos="0 0 0" axis="0 1 0" type="slide"/>
      <joint pos="0 0 0" axis="0 0 1" type="slide"/>
    </body>
    <body name="vsr_7" pos="4 6 5">
      <inertial pos="0 0 0" mass="0.1" diaginertia="1.66667e-06 1.66667e-06 1.66667e-06"/>
      <joint pos="0 0 0" axis="1 0 0" type="slide"/>
      <joint pos="0 0 0" axis="0 1 0" type="slide"/>
      <joint pos="0 0 0" axis="0 0 1" type="slide"/>
    </body>
    <body name="vsr_8" pos="4 6 6">
      <inertial pos="0 0 0" mass="0.1" diaginertia="1.66667e-06 1.66667e-06 1.66667e-06"/>
      <joint pos="0 0 0" axis="1 0 0" type="slide"/>
      <joint pos="0 0 0" axis="0 1 0" type="slide"/>
      <joint pos="0 0 0" axis="0 0 1" type="slide"/>
    </body>
    <body name="vsr_9" pos="5 4 4">
      <inertial pos="0 0 0" mass="0.1" diaginertia="1.66667e-06 1.66667e-06 1.66667e-06"/>
      <joint pos="0 0 0" axis="1 0 0" type="slide"/>
      <joint pos="0 0 0" axis="0 1 0" type="slide"/>
      <joint pos="0 0 0" axis="0 0 1" type="slide"/>
    </body>
    <body name="vsr_10" pos="5 4 5">
      <inertial pos="0 0 0" mass="0.1" diaginertia="1.66667e-06 1.66667e-06 1.66667e-06"/>
      <joint pos="0 0 0" axis="1 0 0" type="slide"/>
      <joint pos="0 0 0" axis="0 1 0" type="slide"/>
      <joint pos="0 0 0" axis="0 0 1" type="slide"/>
    </body>
    <body name="vsr_11" pos="5 4 6">
      <inertial pos="0 0 0" mass="0.1" diaginertia="1.66667e-06 1.66667e-06 1.66667e-06"/>
      <joint pos="0 0 0" axis="1 0 0" type="slide"/>
      <joint pos="0 0 0" axis="0 1 0" type="slide"/>
      <joint pos="0 0 0" axis="0 0 1" type="slide"/>
    </body>
    <body name="vsr_12" pos="5 5 4">
      <inertial pos="0 0 0" mass="0.1" diaginertia="1.66667e-06 1.66667e-06 1.66667e-06"/>
      <joint pos="0 0 0" axis="1 0 0" type="slide"/>
      <joint pos="0 0 0" axis="0 1 0" type="slide"/>
      <joint pos="0 0 0" axis="0 0 1" type="slide"/>
    </body>
    <body name="vsr_13" pos="5 5 5">
      <inertial pos="0 0 0" mass="0.1" diaginertia="1.66667e-06 1.66667e-06 1.66667e-06"/>
      <joint pos="0 0 0" axis="1 0 0" type="slide"/>
      <joint pos="0 0 0" axis="0 1 0" type="slide"/>
      <joint pos="0 0 0" axis="0 0 1" type="slide"/>
    </body>
    <body name="vsr_14" pos="5 5 6">
      <inertial pos="0 0 0" mass="0.1" diaginertia="1.66667e-06 1.66667e-06 1.66667e-06"/>
      <joint pos="0 0 0" axis="1 0 0" type="slide"/>
      <joint pos="0 0 0" axis="0 1 0" type="slide"/>
      <joint pos="0 0 0" axis="0 0 1" type="slide"/>
    </body>
    <body name="vsr_15" pos="5 6 4">
      <inertial pos="0 0 0" mass="0.1" diaginertia="1.66667e-06 1.66667e-06 1.66667e-06"/>
      <joint pos="0 0 0" axis="1 0 0" type="slide"/>
      <joint pos="0 0 0" axis="0 1 0" type="slide"/>
      <joint pos="0 0 0" axis="0 0 1" type="slide"/>
    </body>
    <body name="vsr_16" pos="5 6 5">
      <inertial pos="0 0 0" mass="0.1" diaginertia="1.66667e-06 1.66667e-06 1.66667e-06"/>
      <joint pos="0 0 0" axis="1 0 0" type="slide"/>
      <joint pos="0 0 0" axis="0 1 0" type="slide"/>
      <joint pos="0 0 0" axis="0 0 1" type="slide"/>
    </body>
    <body name="vsr_17" pos="5 6 6">
      <inertial pos="0 0 0" mass="0.1" diaginertia="1.66667e-06 1.66667e-06 1.66667e-06"/>
      <joint pos="0 0 0" axis="1 0 0" type="slide"/>
      <joint pos="0 0 0" axis="0 1 0" type="slide"/>
      <joint pos="0 0 0" axis="0 0 1" type="slide"/>
    </body>
    <body name="vsr_18" pos="6 4 4">
      <inertial pos="0 0 0" mass="0.1" diaginertia="1.66667e-06 1.66667e-06 1.66667e-06"/>
      <joint pos="0 0 0" axis="1 0 0" type="slide"/>
      <joint pos="0 0 0" axis="0 1 0" type="slide"/>
      <joint pos="0 0 0" axis="0 0 1" type="slide"/>
    </body>
    <body name="vsr_19" pos="6 4 5">
      <inertial pos="0 0 0" mass="0.1" diaginertia="1.66667e-06 1.66667e-06 1.66667e-06"/>
      <joint pos="0 0 0" axis="1 0 0" type="slide"/>
      <joint pos="0 0 0" axis="0 1 0" type="slide"/>
      <joint pos="0 0 0" axis="0 0 1" type="slide"/>
    </body>
    <body name="vsr_20" pos="6 4 6">
      <inertial pos="0 0 0" mass="0.1" diaginertia="1.66667e-06 1.66667e-06 1.66667e-06"/>
      <joint pos="0 0 0" axis="1 0 0" type="slide"/>
      <joint pos="0 0 0" axis="0 1 0" type="slide"/>
      <joint pos="0 0 0" axis="0 0 1" type="slide"/>
    </body>
    <body name="vsr_21" pos="6 5 4">
      <inertial pos="0 0 0" mass="0.1" diaginertia="1.66667e-06 1.66667e-06 1.66667e-06"/>
      <joint pos="0 0 0" axis="1 0 0" type="slide"/>
      <joint pos="0 0 0" axis="0 1 0" type="slide"/>
      <joint pos="0 0 0" axis="0 0 1" type="slide"/>
    </body>
    <body name="vsr_22" pos="6 5 5">
      <inertial pos="0 0 0" mass="0.1" diaginertia="1.66667e-06 1.66667e-06 1.66667e-06"/>
      <joint pos="0 0 0" axis="1 0 0" type="slide"/>
      <joint pos="0 0 0" axis="0 1 0" type="slide"/>
      <joint pos="0 0 0" axis="0 0 1" type="slide"/>
    </body>
    <body name="vsr_23" pos="6 5 6">
      <inertial pos="0 0 0" mass="0.1" diaginertia="1.66667e-06 1.66667e-06 1.66667e-06"/>
      <joint pos="0 0 0" axis="1 0 0" type="slide"/>
      <joint pos="0 0 0" axis="0 1 0" type="slide"/>
      <joint pos="0 0 0" axis="0 0 1" type="slide"/>
    </body>
    <body name="vsr_24" pos="6 6 4">
      <inertial pos="0 0 0" mass="0.1" diaginertia="1.66667e-06 1.66667e-06 1.66667e-06"/>
      <joint pos="0 0 0" axis="1 0 0" type="slide"/>
      <joint pos="0 0 0" axis="0 1 0" type="slide"/>
      <joint pos="0 0 0" axis="0 0 1" type="slide"/>
    </body>
    <body name="vsr_25" pos="6 6 5">
      <inertial pos="0 0 0" mass="0.1" diaginertia="1.66667e-06 1.66667e-06 1.66667e-06"/>
      <joint pos="0 0 0" axis="1 0 0" type="slide"/>
      <joint pos="0 0 0" axis="0 1 0" type="slide"/>
      <joint pos="0 0 0" axis="0 0 1" type="slide"/>
    </body>
    <body name="vsr_26" pos="6 6 6">
      <inertial pos="0 0 0" mass="0.1" diaginertia="1.66667e-06 1.66667e-06 1.66667e-06"/>
      <joint pos="0 0 0" axis="1 0 0" type="slide"/>
      <joint pos="0 0 0" axis="0 1 0" type="slide"/>
      <joint pos="0 0 0" axis="0 0 1" type="slide"/>
    </body>
    <body name="vsr_27" pos="7 4 4">
      <inertial pos="0 0 0" mass="0.1" diaginertia="1.66667e-06 1.66667e-06 1.66667e-06"/>
      <joint pos="0 0 0" axis="1 0 0" type="slide"/>
      <joint pos="0 0 0" axis="0 1 0" type="slide"/>
      <joint pos="0 0 0" axis="0 0 1" type="slide"/>
    </body>
    <body name="vsr_28" pos="7 4 5">
      <inertial pos="0 0 0" mass="0.1" diaginertia="1.66667e-06 1.66667e-06 1.66667e-06"/>
      <joint pos="0 0 0" axis="1 0 0" type="slide"/>
      <joint pos="0 0 0" axis="0 1 0" type="slide"/>
      <joint pos="0 0 0" axis="0 0 1" type="slide"/>
    </body>
    <body name="vsr_29" pos="7 4 6">
      <inertial pos="0 0 0" mass="0.1" diaginertia="1.66667e-06 1.66667e-06 1.66667e-06"/>
      <joint pos="0 0 0" axis="1 0 0" type="slide"/>
      <joint pos="0 0 0" axis="0 1 0" type="slide"/>
      <joint pos="0 0 0" axis="0 0 1" type="slide"/>
    </body>
    <body name="vsr_30" pos="7 5 3">
      <inertial pos="0 0 0" mass="0.1" diaginertia="1.66667e-06 1.66667e-06 1.66667e-06"/>
      <joint pos="0 0 0" axis="1 0 0" type="slide"/>
      <joint pos="0 0 0" axis="0 1 0" type="slide"/>
      <joint pos="0 0 0" axis="0 0 1" type="slide"/>
    </body>
    <body name="vsr_31" pos="7 5 4">
      <inertial pos="0 0 0" mass="0.1" diaginertia="1.66667e-06 1.66667e-06 1.66667e-06"/>
      <joint pos="0 0 0" axis="1 0 0" type="slide"/>
      <joint pos="0 0 0" axis="0 1 0" type="slide"/>
      <joint pos="0 0 0" axis="0 0 1" type="slide"/>
    </body>
    <body name="vsr_32" pos="7 5 5">
      <inertial pos="0 0 0" mass="0.1" diaginertia="1.66667e-06 1.66667e-06 1.66667e-06"/>
      <joint pos="0 0 0" axis="1 0 0" type="slide"/>
      <joint pos="0 0 0" axis="0 1 0" type="slide"/>
      <joint pos="0 0 0" axis="0 0 1" type="slide"/>
    </body>
    <body name="vsr_33" pos="7 5 6">
      <inertial pos="0 0 0" mass="0.1" diaginertia="1.66667e-06 1.66667e-06 1.66667e-06"/>
      <joint pos="0 0 0" axis="1 0 0" type="slide"/>
      <joint pos="0 0 0" axis="0 1 0" type="slide"/>
      <joint pos="0 0 0" axis="0 0 1" type="slide"/>
    </body>
    <body name="vsr_34" pos="7 5 7">
      <inertial pos="0 0 0" mass="0.1" diaginertia="1.66667e-06 1.66667e-06 1.66667e-06"/>
      <joint pos="0 0 0" axis="1 0 0" type="slide"/>
      <joint pos="0 0 0" axis="0 1 0" type="slide"/>
      <joint pos="0 0 0" axis="0 0 1" type="slide"/>
    </body>
    <body name="vsr_35" pos="7 6 3">
      <inertial pos="0 0 0" mass="0.1" diaginertia="1.66667e-06 1.66667e-06 1.66667e-06"/>
      <joint pos="0 0 0" axis="1 0 0" type="slide"/>
      <joint pos="0 0 0" axis="0 1 0" type="slide"/>
      <joint pos="0 0 0" axis="0 0 1" type="slide"/>
    </body>
    <body name="vsr_36" pos="7 6 4">
      <inertial pos="0 0 0" mass="0.1" diaginertia="1.66667e-06 1.66667e-06 1.66667e-06"/>
      <joint pos="0 0 0" axis="1 0 0" type="slide"/>
      <joint pos="0 0 0" axis="0 1 0" type="slide"/>
      <joint pos="0 0 0" axis="0 0 1" type="slide"/>
    </body>
    <body name="vsr_37" pos="7 6 5">
      <inertial pos="0 0 0" mass="0.1" diaginertia="1.66667e-06 1.66667e-06 1.66667e-06"/>
      <joint pos="0 0 0" axis="1 0 0" type="slide"/>
      <joint pos="0 0 0" axis="0 1 0" type="slide"/>
      <joint pos="0 0 0" axis="0 0 1" type="slide"/>
    </body>
    <body name="vsr_38" pos="7 6 6">
      <inertial pos="0 0 0" mass="0.1" diaginertia="1.66667e-06 1.66667e-06 1.66667e-06"/>
      <joint pos="0 0 0" axis="1 0 0" type="slide"/>
      <joint pos="0 0 0" axis="0 1 0" type="slide"/>
      <joint pos="0 0 0" axis="0 0 1" type="slide"/>
    </body>
    <body name="vsr_39" pos="7 6 7">
      <inertial pos="0 0 0" mass="0.1" diaginertia="1.66667e-06 1.66667e-06 1.66667e-06"/>
      <joint pos="0 0 0" axis="1 0 0" type="slide"/>
      <joint pos="0 0 0" axis="0 1 0" type="slide"/>
      <joint pos="0 0 0" axis="0 0 1" type="slide"/>
    </body>
    <body name="vsr_40" pos="7 7 4">
      <inertial pos="0 0 0" mass="0.1" diaginertia="1.66667e-06 1.66667e-06 1.66667e-06"/>
      <joint pos="0 0 0" axis="1 0 0" type="slide"/>
      <joint pos="0 0 0" axis="0 1 0" type="slide"/>
      <joint pos="0 0 0" axis="0 0 1" type="slide"/>
    </body>
    <body name="vsr_41" pos="7 7 5">
      <inertial pos="0 0 0" mass="0.1" diaginertia="1.66667e-06 1.66667e-06 1.66667e-06"/>
      <joint pos="0 0 0" axis="1 0 0" type="slide"/>
      <joint pos="0 0 0" axis="0 1 0" type="slide"/>
      <joint pos="0 0 0" axis="0 0 1" type="slide"/>
    </body>
    <body name="vsr_42" pos="7 7 6">
      <inertial pos="0 0 0" mass="0.1" diaginertia="1.66667e-06 1.66667e-06 1.66667e-06"/>
      <joint pos="0 0 0" axis="1 0 0" type="slide"/>
      <joint pos="0 0 0" axis="0 1 0" type="slide"/>
      <joint pos="0 0 0" axis="0 0 1" type="slide"/>
    </body>
    <body name="vsr_43" pos="8 4 4">
      <inertial pos="0 0 0" mass="0.1" diaginertia="1.66667e-06 1.66667e-06 1.66667e-06"/>
      <joint pos="0 0 0" axis="1 0 0" type="slide"/>
      <joint pos="0 0 0" axis="0 1 0" type="slide"/>
      <joint pos="0 0 0" axis="0 0 1" type="slide"/>
    </body>
    <body name="vsr_44" pos="8 4 5">
      <inertial pos="0 0 0" mass="0.1" diaginertia="1.66667e-06 1.66667e-06 1.66667e-06"/>
      <joint pos="0 0 0" axis="1 0 0" type="slide"/>
      <joint pos="0 0 0" axis="0 1 0" type="slide"/>
      <joint pos="0 0 0" axis="0 0 1" type="slide"/>
    </body>
    <body name="vsr_45" pos="8 4 6">
      <inertial pos="0 0 0" mass="0.1" diaginertia="1.66667e-06 1.66667e-06 1.66667e-06"/>
      <joint pos="0 0 0" axis="1 0 0" type="slide"/>
      <joint pos="0 0 0" axis="0 1 0" type="slide"/>
      <joint pos="0 0 0" axis="0 0 1" type="slide"/>
    </body>
    <body name="vsr_46" pos="8 5 3">
      <inertial pos="0 0 0" mass="0.1" diaginertia="1.66667e-06 1.66667e-06 1.66667e-06"/>
      <joint pos="0 0 0" axis="1 0 0" type="slide"/>
      <joint pos="0 0 0" axis="0 1 0" type="slide"/>
      <joint pos="0 0 0" axis="0 0 1" type="slide"/>
    </body>
    <body name="vsr_47" pos="8 5 4">
      <inertial pos="0 0 0" mass="0.1" diaginertia="1.66667e-06 1.66667e-06 1.66667e-06"/>
      <joint pos="0 0 0" axis="1 0 0" type="slide"/>
      <joint pos="0 0 0" axis="0 1 0" type="slide"/>
      <joint pos="0 0 0" axis="0 0 1" type="slide"/>
    </body>
    <body name="vsr_48" pos="8 5 5">
      <inertial pos="0 0 0" mass="0.1" diaginertia="1.66667e-06 1.66667e-06 1.66667e-06"/>
      <joint pos="0 0 0" axis="1 0 0" type="slide"/>
      <joint pos="0 0 0" axis="0 1 0" type="slide"/>
      <joint pos="0 0 0" axis="0 0 1" type="slide"/>
    </body>
    <body name="vsr_49" pos="8 5 6">
      <inertial pos="0 0 0" mass="0.1" diaginertia="1.66667e-06 1.66667e-06 1.66667e-06"/>
      <joint pos="0 0 0" axis="1 0 0" type="slide"/>
      <joint pos="0 0 0" axis="0 1 0" type="slide"/>
      <joint pos="0 0 0" axis="0 0 1" type="slide"/>
    </body>
    <body name="vsr_50" pos="8 5 7">
      <inertial pos="0 0 0" mass="0.1" diaginertia="1.66667e-06 1.66667e-06 1.66667e-06"/>
      <joint pos="0 0 0" axis="1 0 0" type="slide"/>
      <joint pos="0 0 0" axis="0 1 0" type="slide"/>
      <joint pos="0 0 0" axis="0 0 1" type="slide"/>
    </body>
    <body name="vsr_51" pos="8 6 3">
      <inertial pos="0 0 0" mass="0.1" diaginertia="1.66667e-06 1.66667e-06 1.66667e-06"/>
      <joint pos="0 0 0" axis="1 0 0" type="slide"/>
      <joint pos="0 0 0" axis="0 1 0" type="slide"/>
      <joint pos="0 0 0" axis="0 0 1" type="slide"/>
    </body>
    <body name="vsr_52" pos="8 6 4">
      <inertial pos="0 0 0" mass="0.1" diaginertia="1.66667e-06 1.66667e-06 1.66667e-06"/>
      <joint pos="0 0 0" axis="1 0 0" type="slide"/>
      <joint pos="0 0 0" axis="0 1 0" type="slide"/>
      <joint pos="0 0 0" axis="0 0 1" type="slide"/>
    </body>
    <body name="vsr_53" pos="8 6 5">
      <inertial pos="0 0 0" mass="0.1" diaginertia="1.66667e-06 1.66667e-06 1.66667e-06"/>
      <joint pos="0 0 0" axis="1 0 0" type="slide"/>
      <joint pos="0 0 0" axis="0 1 0" type="slide"/>
      <joint pos="0 0 0" axis="0 0 1" type="slide"/>
    </body>
    <body name="vsr_54" pos="8 6 6">
      <inertial pos="0 0 0" mass="0.1" diaginertia="1.66667e-06 1.66667e-06 1.66667e-06"/>
      <joint pos="0 0 0" axis="1 0 0" type="slide"/>
      <joint pos="0 0 0" axis="0 1 0" type="slide"/>
      <joint pos="0 0 0" axis="0 0 1" type="slide"/>
    </body>
    <body name="vsr_55" pos="8 6 7">
      <inertial pos="0 0 0" mass="0.1" diaginertia="1.66667e-06 1.66667e-06 1.66667e-06"/>
      <joint pos="0 0 0" axis="1 0 0" type="slide"/>
      <joint pos="0 0 0" axis="0 1 0" type="slide"/>
      <joint pos="0 0 0" axis="0 0 1" type="slide"/>
    </body>
    <body name="vsr_56" pos="8 7 4">
      <inertial pos="0 0 0" mass="0.1" diaginertia="1.66667e-06 1.66667e-06 1.66667e-06"/>
      <joint pos="0 0 0" axis="1 0 0" type="slide"/>
      <joint pos="0 0 0" axis="0 1 0" type="slide"/>
      <joint pos="0 0 0" axis="0 0 1" type="slide"/>
    </body>
    <body name="vsr_57" pos="8 7 5">
      <inertial pos="0 0 0" mass="0.1" diaginertia="1.66667e-06 1.66667e-06 1.66667e-06"/>
      <joint pos="0 0 0" axis="1 0 0" type="slide"/>
      <joint pos="0 0 0" axis="0 1 0" type="slide"/>
      <joint pos="0 0 0" axis="0 0 1" type="slide"/>
    </body>
    <body name="vsr_58" pos="8 7 6">
      <inertial pos="0 0 0" mass="0.1" diaginertia="1.66667e-06 1.66667e-06 1.66667e-06"/>
      <joint pos="0 0 0" axis="1 0 0" type="slide"/>
      <joint pos="0 0 0" axis="0 1 0" type="slide"/>
      <joint pos="0 0 0" axis="0 0 1" type="slide"/>
    </body>
    <body name="vsr_59" pos="9 5 4">
      <inertial pos="0 0 0" mass="0.1" diaginertia="1.66667e-06 1.66667e-06 1.66667e-06"/>
      <joint pos="0 0 0" axis="1 0 0" type="slide"/>
      <joint pos="0 0 0" axis="0 1 0" type="slide"/>
      <joint pos="0 0 0" axis="0 0 1" type="slide"/>
    </body>
    <body name="vsr_60" pos="9 5 5">
      <inertial pos="0 0 0" mass="0.1" diaginertia="1.66667e-06 1.66667e-06 1.66667e-06"/>
      <joint pos="0 0 0" axis="1 0 0" type="slide"/>
      <joint pos="0 0 0" axis="0 1 0" type="slide"/>
      <joint pos="0 0 0" axis="0 0 1" type="slide"/>
    </body>
    <body name="vsr_61" pos="9 5 6">
      <inertial pos="0 0 0" mass="0.1" diaginertia="1.66667e-06 1.66667e-06 1.66667e-06"/>
      <joint pos="0 0 0" axis="1 0 0" type="slide"/>
      <joint pos="0 0 0" axis="0 1 0" type="slide"/>
      <joint pos="0 0 0" axis="0 0 1" type="slide"/>
    </body>
    <body name="vsr_62" pos="9 6 4">
      <inertial pos="0 0 0" mass="0.1" diaginertia="1.66667e-06 1.66667e-06 1.66667e-06"/>
      <joint pos="0 0 0" axis="1 0 0" type="slide"/>
      <joint pos="0 0 0" axis="0 1 0" type="slide"/>
      <joint pos="0 0 0" axis="0 0 1" type="slide"/>
    </body>
    <body name="vsr_63" pos="9 6 5">
      <inertial pos="0 0 0" mass="0.1" diaginertia="1.66667e-06 1.66667e-06 1.66667e-06"/>
      <joint pos="0 0 0" axis="1 0 0" type="slide"/>
      <joint pos="0 0 0" axis="0 1 0" type="slide"/>
      <joint pos="0 0 0" axis="0 0 1" type="slide"/>
    </body>
    <body name="vsr_64" pos="9 6 6">
      <inertial pos="0 0 0" mass="0.1" diaginertia="1.66667e-06 1.66667e-06 1.66667e-06"/>
      <joint pos="0 0 0" axis="1 0 0" type="slide"/>
      <joint pos="0 0 0" axis="0 1 0" type="slide"/>
      <joint pos="0 0 0" axis="0 0 1" type="slide"/>
    </body>
  </worldbody>

  <deformable>
    <flex name="vsr" rgba="0.1 0.9 0.1 1" dim="3" body="vsr_0 vsr_1 vsr_2 vsr_3 vsr_4 vsr_5 vsr_6 vsr_7 vsr_8 vsr_9 vsr_10 vsr_11 vsr_12 vsr_13 vsr_14 vsr_15 vsr_16 vsr_17 vsr_18 vsr_19 vsr_20 vsr_21 vsr_22 vsr_23 vsr_24 vsr_25 vsr_26 vsr_27 vsr_28 vsr_29 vsr_30 vsr_31 vsr_32 vsr_33 vsr_34 vsr_35 vsr_36 vsr_37 vsr_38 vsr_39 vsr_40 vsr_41 vsr_42 vsr_43 vsr_44 vsr_45 vsr_46 vsr_47 vsr_48 vsr_49 vsr_50 vsr_51 vsr_52 vsr_53 vsr_54 vsr_55 vsr_56 vsr_57 vsr_58 vsr_59 vsr_60 vsr_61 vsr_62 vsr_63 vsr_64" element="0 4 3 13 0 1 4 13 0 10 1 13 0 9 10 13 0 12 9 13 0 3 12 13 1 5 4 14 1 2 5 14 1 11 2 14 1 10 11 14 1 13 10 14 1 4 13 14 3 7 6 16 3 4 7 16 3 13 4 16 3 12 13 16 3 15 12 16 3 6 15 16 4 8 7 17 4 5 8 17 4 14 5 17 4 13 14 17 4 16 13 17 4 7 16 17 9 13 12 22 9 10 13 22 9 19 10 22 9 18 19 22 9 21 18 22 9 12 21 22 10 14 13 23 10 11 14 23 10 20 11 23 10 19 20 23 10 22 19 23 10 13 22 23 12 16 15 25 12 13 16 25 12 22 13 25 12 21 22 25 12 24 21 25 12 15 24 25 13 17 16 26 13 14 17 26 13 23 14 26 13 22 23 26 13 25 22 26 13 16 25 26 18 22 21 32 18 19 22 32 18 28 19 32 18 27 28 32 18 31 27 32 18 21 31 32 19 23 22 33 19 20 23 33 19 29 20 33 19 28 29 33 19 32 28 33 19 22 32 33 21 25 24 37 21 22 25 37 21 32 22 37 21 31 32 37 21 36 31 37 21 24 36 37 22 26 25 38 22 23 26 38 22 33 23 38 22 32 33 38 22 37 32 38 22 25 37 38 27 32 31 48 27 28 32 48 27 44 28 48 27 43 44 48 27 47 43 48 27 31 47 48 28 33 32 49 28 29 33 49 28 45 29 49 28 44 45 49 28 48 44 49 28 32 48 49 30 36 35 52 30 31 36 52 30 47 31 52 30 46 47 52 30 51 46 52 30 35 51 52 31 37 36 53 31 32 37 53 31 48 32 53 31 47 48 53 31 52 47 53 31 36 52 53 32 38 37 54 32 33 38 54 32 49 33 54 32 48 49 54 32 53 48 54 32 37 53 54 33 39 38 55 33 34 39 55 33 50 34 55 33 49 50 55 33 54 49 55 33 38 54 55 36 41 40 57 36 37 41 57 36 53 37 57 36 52 53 57 36 56 52 57 36 40 56 57 37 42 41 58 37 38 42 58 37 54 38 58 37 53 54 58 37 57 53 58 37 41 57 58 47 53 52 63 47 48 53 63 47 60 48 63 47 59 60 63 47 62 59 63 47 52 62 63 48 54 53 64 48 49 54 64 48 61 49 64 48 60 61 64 48 63 60 64 48 53 63 64">

      <contact solref="0.01 1" solimp="0.95 0.99 0.0001 0.5 2" selfcollide="none"/>
      <elasticity young="250" poisson="0.3"/>
      <edge damping="1"/>
    </flex>
  </deformable>
</mujoco>
