<?xml version="1.0" ?>
<mujoco model="MuJoCo Model">
  <compiler angle="radian" meshdir="asset/" texturedir="asset/"/>
  <option timestep="0.001" tolerance="1e-06" integrator="implicitfast"/>
  <size memory="2000M"/>
  <visual>
    <map stiffness="700" fogstart="1" fogend="15" zfar="40" haze="1" shadowscale="0.5"/>
    <rgba haze="0.15 0.25 0.35 1"/>
  </visual>
  <statistic meansize="0.05"/>
  <asset>
    <texture type="skybox" builtin="gradient" rgb1="0.3 0.5 0.7" rgb2="0 0 0" width="512" height="3072"/>
    <texture type="2d" name="texplane" builtin="checker" mark="cross" rgb1="0.2 0.3 0.4" rgb2="0.1 0.15 0.2" markrgb="0.8 0.8 0.8" width="512" height="512"/>
    <material name="matplane" texture="texplane" texuniform="true" texrepeat="10 10" reflectance="0.3"/>
  </asset>
  <worldbody>
    <geom name="ground" size="0 0 1" pos="0 0 -2" type="plane" condim="1" material="matplane"/>
    <light pos="30 30 20" dir="0 0 -1" diffuse="0.4 0.4 0.4" specular="0.1 0.1 0.1"/>
    <light pos="-20 -20 40" dir="0.0990148 0.0990148 -0.990148" directional="true" diffuse="0.8 0.8 0.8" specular="0.2 0.2 0.2"/>
    <body name="target" pos="-60 3 3.5">
      <geom size="1 1 3" type="box" rgba="1 0 0 0.7"/>
      <site name="site_-60_3_3.5" pos="0 0 0" size="0.005"/>
    </body>
    <body name="vsr_0" pos="4 4 4">
      <inertial pos="0 0 0" mass="0.1" diaginertia="1.66667e-06 1.66667e-06 1.66667e-06"/>
      <joint pos="0 0 0" axis="1 0 0" type="slide"/>
      <joint pos="0 0 0" axis="0 1 0" type="slide"/>
      <joint pos="0 0 0" axis="0 0 1" type="slide"/>
      <site name="site_4_4_4" pos="0 0 0" size="0.005"/>
    </body>
    <body name="vsr_1" pos="4 4 5">
      <inertial pos="0 0 0" mass="0.1" diaginertia="1.66667e-06 1.66667e-06 1.66667e-06"/>
      <joint pos="0 0 0" axis="1 0 0" type="slide"/>
      <joint pos="0 0 0" axis="0 1 0" type="slide"/>
      <joint pos="0 0 0" axis="0 0 1" type="slide"/>
      <site name="site_4_4_5" pos="0 0 0" size="0.005"/>
    </body>
    <body name="vsr_2" pos="4 5 4">
      <inertial pos="0 0 0" mass="0.1" diaginertia="1.66667e-06 1.66667e-06 1.66667e-06"/>
      <joint pos="0 0 0" axis="1 0 0" type="slide"/>
      <joint pos="0 0 0" axis="0 1 0" type="slide"/>
      <joint pos="0 0 0" axis="0 0 1" type="slide"/>
      <site name="site_4_5_4" pos="0 0 0" size="0.005"/>
    </body>
    <body name="vsr_3" pos="4 5 5">
      <inertial pos="0 0 0" mass="0.1" diaginertia="1.66667e-06 1.66667e-06 1.66667e-06"/>
      <joint pos="0 0 0" axis="1 0 0" type="slide"/>
      <joint pos="0 0 0" axis="0 1 0" type="slide"/>
      <joint pos="0 0 0" axis="0 0 1" type="slide"/>
      <site name="site_4_5_5" pos="0 0 0" size="0.005"/>
    </body>
    <body name="vsr_4" pos="4 6 4">
      <inertial pos="0 0 0" mass="0.1" diaginertia="1.66667e-06 1.66667e-06 1.66667e-06"/>
      <joint pos="0 0 0" axis="1 0 0" type="slide"/>
      <joint pos="0 0 0" axis="0 1 0" type="slide"/>
      <joint pos="0 0 0" axis="0 0 1" type="slide"/>
      <site name="site_4_6_4" pos="0 0 0" size="0.005"/>
    </body>
    <body name="vsr_5" pos="4 6 5">
      <inertial pos="0 0 0" mass="0.1" diaginertia="1.66667e-06 1.66667e-06 1.66667e-06"/>
      <joint pos="0 0 0" axis="1 0 0" type="slide"/>
      <joint pos="0 0 0" axis="0 1 0" type="slide"/>
      <joint pos="0 0 0" axis="0 0 1" type="slide"/>
      <site name="site_4_6_5" pos="0 0 0" size="0.005"/>
    </body>
    <body name="vsr_6" pos="5 4 4">
      <inertial pos="0 0 0" mass="0.1" diaginertia="1.66667e-06 1.66667e-06 1.66667e-06"/>
      <joint pos="0 0 0" axis="1 0 0" type="slide"/>
      <joint pos="0 0 0" axis="0 1 0" type="slide"/>
      <joint pos="0 0 0" axis="0 0 1" type="slide"/>
      <site name="site_5_4_4" pos="0 0 0" size="0.005"/>
    </body>
    <body name="vsr_7" pos="5 4 5">
      <inertial pos="0 0 0" mass="0.1" diaginertia="1.66667e-06 1.66667e-06 1.66667e-06"/>
      <joint pos="0 0 0" axis="1 0 0" type="slide"/>
      <joint pos="0 0 0" axis="0 1 0" type="slide"/>
      <joint pos="0 0 0" axis="0 0 1" type="slide"/>
      <site name="site_5_4_5" pos="0 0 0" size="0.005"/>
    </body>
    <body name="vsr_8" pos="5 5 4">
      <inertial pos="0 0 0" mass="0.1" diaginertia="1.66667e-06 1.66667e-06 1.66667e-06"/>
      <joint pos="0 0 0" axis="1 0 0" type="slide"/>
      <joint pos="0 0 0" axis="0 1 0" type="slide"/>
      <joint pos="0 0 0" axis="0 0 1" type="slide"/>
      <site name="site_5_5_4" pos="0 0 0" size="0.005"/>
    </body>
    <body name="vsr_9" pos="5 5 5">
      <inertial pos="0 0 0" mass="0.1" diaginertia="1.66667e-06 1.66667e-06 1.66667e-06"/>
      <joint pos="0 0 0" axis="1 0 0" type="slide"/>
      <joint pos="0 0 0" axis="0 1 0" type="slide"/>
      <joint pos="0 0 0" axis="0 0 1" type="slide"/>
      <site name="site_5_5_5" pos="0 0 0" size="0.005"/>
    </body>
    <body name="vsr_10" pos="5 6 4">
      <inertial pos="0 0 0" mass="0.1" diaginertia="1.66667e-06 1.66667e-06 1.66667e-06"/>
      <joint pos="0 0 0" axis="1 0 0" type="slide"/>
      <joint pos="0 0 0" axis="0 1 0" type="slide"/>
      <joint pos="0 0 0" axis="0 0 1" type="slide"/>
      <site name="site_5_6_4" pos="0 0 0" size="0.005"/>
    </body>
    <body name="vsr_11" pos="5 6 5">
      <inertial pos="0 0 0" mass="0.1" diaginertia="1.66667e-06 1.66667e-06 1.66667e-06"/>
      <joint pos="0 0 0" axis="1 0 0" type="slide"/>
      <joint pos="0 0 0" axis="0 1 0" type="slide"/>
      <joint pos="0 0 0" axis="0 0 1" type="slide"/>
      <site name="site_5_6_5" pos="0 0 0" size="0.005"/>
    </body>
    <body name="vsr_12" pos="6 4 4">
      <inertial pos="0 0 0" mass="0.1" diaginertia="1.66667e-06 1.66667e-06 1.66667e-06"/>
      <joint pos="0 0 0" axis="1 0 0" type="slide"/>
      <joint pos="0 0 0" axis="0 1 0" type="slide"/>
      <joint pos="0 0 0" axis="0 0 1" type="slide"/>
      <site name="site_6_4_4" pos="0 0 0" size="0.005"/>
    </body>
    <body name="vsr_13" pos="6 4 5">
      <inertial pos="0 0 0" mass="0.1" diaginertia="1.66667e-06 1.66667e-06 1.66667e-06"/>
      <joint pos="0 0 0" axis="1 0 0" type="slide"/>
      <joint pos="0 0 0" axis="0 1 0" type="slide"/>
      <joint pos="0 0 0" axis="0 0 1" type="slide"/>
      <site name="site_6_4_5" pos="0 0 0" size="0.005"/>
    </body>
    <body name="vsr_14" pos="6 5 4">
      <inertial pos="0 0 0" mass="0.1" diaginertia="1.66667e-06 1.66667e-06 1.66667e-06"/>
      <joint pos="0 0 0" axis="1 0 0" type="slide"/>
      <joint pos="0 0 0" axis="0 1 0" type="slide"/>
      <joint pos="0 0 0" axis="0 0 1" type="slide"/>
      <site name="site_6_5_4" pos="0 0 0" size="0.005"/>
    </body>
    <body name="vsr_15" pos="6 5 5">
      <inertial pos="0 0 0" mass="0.1" diaginertia="1.66667e-06 1.66667e-06 1.66667e-06"/>
      <joint pos="0 0 0" axis="1 0 0" type="slide"/>
      <joint pos="0 0 0" axis="0 1 0" type="slide"/>
      <joint pos="0 0 0" axis="0 0 1" type="slide"/>
      <site name="site_6_5_5" pos="0 0 0" size="0.005"/>
    </body>
    <body name="vsr_16" pos="6 6 4">
      <inertial pos="0 0 0" mass="0.1" diaginertia="1.66667e-06 1.66667e-06 1.66667e-06"/>
      <joint pos="0 0 0" axis="1 0 0" type="slide"/>
      <joint pos="0 0 0" axis="0 1 0" type="slide"/>
      <joint pos="0 0 0" axis="0 0 1" type="slide"/>
      <site name="site_6_6_4" pos="0 0 0" size="0.005"/>
    </body>
    <body name="vsr_17" pos="6 6 5">
      <inertial pos="0 0 0" mass="0.1" diaginertia="1.66667e-06 1.66667e-06 1.66667e-06"/>
      <joint pos="0 0 0" axis="1 0 0" type="slide"/>
      <joint pos="0 0 0" axis="0 1 0" type="slide"/>
      <joint pos="0 0 0" axis="0 0 1" type="slide"/>
      <site name="site_6_6_5" pos="0 0 0" size="0.005"/>
    </body>
    <body name="vsr_18" pos="7 4 4">
      <inertial pos="0 0 0" mass="0.1" diaginertia="1.66667e-06 1.66667e-06 1.66667e-06"/>
      <joint pos="0 0 0" axis="1 0 0" type="slide"/>
      <joint pos="0 0 0" axis="0 1 0" type="slide"/>
      <joint pos="0 0 0" axis="0 0 1" type="slide"/>
      <site name="site_7_4_4" pos="0 0 0" size="0.005"/>
    </body>
    <body name="vsr_19" pos="7 4 5">
      <inertial pos="0 0 0" mass="0.1" diaginertia="1.66667e-06 1.66667e-06 1.66667e-06"/>
      <joint pos="0 0 0" axis="1 0 0" type="slide"/>
      <joint pos="0 0 0" axis="0 1 0" type="slide"/>
      <joint pos="0 0 0" axis="0 0 1" type="slide"/>
      <site name="site_7_4_5" pos="0 0 0" size="0.005"/>
    </body>
    <body name="vsr_20" pos="7 5 4">
      <inertial pos="0 0 0" mass="0.1" diaginertia="1.66667e-06 1.66667e-06 1.66667e-06"/>
      <joint pos="0 0 0" axis="1 0 0" type="slide"/>
      <joint pos="0 0 0" axis="0 1 0" type="slide"/>
      <joint pos="0 0 0" axis="0 0 1" type="slide"/>
      <site name="site_7_5_4" pos="0 0 0" size="0.005"/>
    </body>
    <body name="vsr_21" pos="7 5 5">
      <inertial pos="0 0 0" mass="0.1" diaginertia="1.66667e-06 1.66667e-06 1.66667e-06"/>
      <joint pos="0 0 0" axis="1 0 0" type="slide"/>
      <joint pos="0 0 0" axis="0 1 0" type="slide"/>
      <joint pos="0 0 0" axis="0 0 1" type="slide"/>
      <site name="site_7_5_5" pos="0 0 0" size="0.005"/>
    </body>
    <body name="vsr_22" pos="7 6 4">
      <inertial pos="0 0 0" mass="0.1" diaginertia="1.66667e-06 1.66667e-06 1.66667e-06"/>
      <joint pos="0 0 0" axis="1 0 0" type="slide"/>
      <joint pos="0 0 0" axis="0 1 0" type="slide"/>
      <joint pos="0 0 0" axis="0 0 1" type="slide"/>
      <site name="site_7_6_4" pos="0 0 0" size="0.005"/>
    </body>
    <body name="vsr_23" pos="7 6 5">
      <inertial pos="0 0 0" mass="0.1" diaginertia="1.66667e-06 1.66667e-06 1.66667e-06"/>
      <joint pos="0 0 0" axis="1 0 0" type="slide"/>
      <joint pos="0 0 0" axis="0 1 0" type="slide"/>
      <joint pos="0 0 0" axis="0 0 1" type="slide"/>
      <site name="site_7_6_5" pos="0 0 0" size="0.005"/>
    </body>
    <body name="vsr_24" pos="8 4 4">
      <inertial pos="0 0 0" mass="0.1" diaginertia="1.66667e-06 1.66667e-06 1.66667e-06"/>
      <joint pos="0 0 0" axis="1 0 0" type="slide"/>
      <joint pos="0 0 0" axis="0 1 0" type="slide"/>
      <joint pos="0 0 0" axis="0 0 1" type="slide"/>
      <site name="site_8_4_4" pos="0 0 0" size="0.005"/>
    </body>
    <body name="vsr_25" pos="8 4 5">
      <inertial pos="0 0 0" mass="0.1" diaginertia="1.66667e-06 1.66667e-06 1.66667e-06"/>
      <joint pos="0 0 0" axis="1 0 0" type="slide"/>
      <joint pos="0 0 0" axis="0 1 0" type="slide"/>
      <joint pos="0 0 0" axis="0 0 1" type="slide"/>
      <site name="site_8_4_5" pos="0 0 0" size="0.005"/>
    </body>
    <body name="vsr_26" pos="8 5 4">
      <inertial pos="0 0 0" mass="0.1" diaginertia="1.66667e-06 1.66667e-06 1.66667e-06"/>
      <joint pos="0 0 0" axis="1 0 0" type="slide"/>
      <joint pos="0 0 0" axis="0 1 0" type="slide"/>
      <joint pos="0 0 0" axis="0 0 1" type="slide"/>
      <site name="site_8_5_4" pos="0 0 0" size="0.005"/>
    </body>
    <body name="vsr_27" pos="8 5 5">
      <inertial pos="0 0 0" mass="0.1" diaginertia="1.66667e-06 1.66667e-06 1.66667e-06"/>
      <joint pos="0 0 0" axis="1 0 0" type="slide"/>
      <joint pos="0 0 0" axis="0 1 0" type="slide"/>
      <joint pos="0 0 0" axis="0 0 1" type="slide"/>
      <site name="site_8_5_5" pos="0 0 0" size="0.005"/>
    </body>
    <body name="vsr_28" pos="8 6 4">
      <inertial pos="0 0 0" mass="0.1" diaginertia="1.66667e-06 1.66667e-06 1.66667e-06"/>
      <joint pos="0 0 0" axis="1 0 0" type="slide"/>
      <joint pos="0 0 0" axis="0 1 0" type="slide"/>
      <joint pos="0 0 0" axis="0 0 1" type="slide"/>
      <site name="site_8_6_4" pos="0 0 0" size="0.005"/>
    </body>
    <body name="vsr_29" pos="8 6 5">
      <inertial pos="0 0 0" mass="0.1" diaginertia="1.66667e-06 1.66667e-06 1.66667e-06"/>
      <joint pos="0 0 0" axis="1 0 0" type="slide"/>
      <joint pos="0 0 0" axis="0 1 0" type="slide"/>
      <joint pos="0 0 0" axis="0 0 1" type="slide"/>
      <site name="site_8_6_5" pos="0 0 0" size="0.005"/>
    </body>
  </worldbody>
  <deformable>
    <flex name="vsr" rgba="0.1 0.9 0.1 1" dim="3" body="vsr_0 vsr_1 vsr_2 vsr_3 vsr_4 vsr_5 vsr_6 vsr_7 vsr_8 vsr_9 vsr_10 vsr_11 vsr_12 vsr_13 vsr_14 vsr_15 vsr_16 vsr_17 vsr_18 vsr_19 vsr_20 vsr_21 vsr_22 vsr_23 vsr_24 vsr_25 vsr_26 vsr_27 vsr_28 vsr_29" element="0 3 2 9 0 1 3 9 0 7 1 9 0 6 7 9 0 8 6 9 0 2 8 9 2 5 4 11 2 3 5 11 2 9 3 11 2 8 9 11 2 10 8 11 2 4 10 11 6 9 8 15 6 7 9 15 6 13 7 15 6 12 13 15 6 14 12 15 6 8 14 15 8 11 10 17 8 9 11 17 8 15 9 17 8 14 15 17 8 16 14 17 8 10 16 17 12 15 14 21 12 13 15 21 12 19 13 21 12 18 19 21 12 20 18 21 12 14 20 21 14 17 16 23 14 15 17 23 14 21 15 23 14 20 21 23 14 22 20 23 14 16 22 23 18 21 20 27 18 19 21 27 18 25 19 27 18 24 25 27 18 26 24 27 18 20 26 27 20 23 22 29 20 21 23 29 20 27 21 29 20 26 27 29 20 28 26 29 20 22 28 29">
      <contact solref="0.01 1" solimp="0.95 0.99 0.0001 0.5 2" selfcollide="none"/>
      <elasticity young="250" poisson="0.3"/>
      <edge damping="1"/>
    </flex>
  </deformable>
  <tendon>
    <spatial name="voxel_4_4_4_spatial_4_4_4_to_5_5_5" width="0.006" rgba="1 0 0 1" stiffness="1" damping="0">
      <site site="site_4_4_4"/>
      <site site="site_5_5_5"/>
    </spatial>
    <spatial name="voxel_4_4_4_spatial_5_5_4_to_4_4_5" width="0.006" rgba="0 1 0 1" stiffness="1" damping="0">
      <site site="site_5_5_4"/>
      <site site="site_4_4_5"/>
    </spatial>
    <spatial name="voxel_4_4_4_spatial_4_5_4_to_5_4_5" width="0.006" rgba="0 0 1 1" stiffness="1" damping="0">
      <site site="site_4_5_4"/>
      <site site="site_5_4_5"/>
    </spatial>
    <spatial name="voxel_4_4_4_spatial_5_4_4_to_4_5_5" width="0.006" rgba="1 0 1 1" stiffness="1" damping="0">
      <site site="site_5_4_4"/>
      <site site="site_4_5_5"/>
    </spatial>
    <spatial name="voxel_4_5_4_spatial_4_5_4_to_5_6_5" width="0.006" rgba="1 0 0 1" stiffness="1" damping="0">
      <site site="site_4_5_4"/>
      <site site="site_5_6_5"/>
    </spatial>
    <spatial name="voxel_4_5_4_spatial_5_6_4_to_4_5_5" width="0.006" rgba="0 1 0 1" stiffness="1" damping="0">
      <site site="site_5_6_4"/>
      <site site="site_4_5_5"/>
    </spatial>
    <spatial name="voxel_4_5_4_spatial_4_6_4_to_5_5_5" width="0.006" rgba="0 0 1 1" stiffness="1" damping="0">
      <site site="site_4_6_4"/>
      <site site="site_5_5_5"/>
    </spatial>
    <spatial name="voxel_4_5_4_spatial_5_5_4_to_4_6_5" width="0.006" rgba="1 0 1 1" stiffness="1" damping="0">
      <site site="site_5_5_4"/>
      <site site="site_4_6_5"/>
    </spatial>
    <spatial name="voxel_5_4_4_spatial_5_4_4_to_6_5_5" width="0.006" rgba="1 0 0 1" stiffness="1" damping="0">
      <site site="site_5_4_4"/>
      <site site="site_6_5_5"/>
    </spatial>
    <spatial name="voxel_5_4_4_spatial_6_5_4_to_5_4_5" width="0.006" rgba="0 1 0 1" stiffness="1" damping="0">
      <site site="site_6_5_4"/>
      <site site="site_5_4_5"/>
    </spatial>
    <spatial name="voxel_5_4_4_spatial_5_5_4_to_6_4_5" width="0.006" rgba="0 0 1 1" stiffness="1" damping="0">
      <site site="site_5_5_4"/>
      <site site="site_6_4_5"/>
    </spatial>
    <spatial name="voxel_5_4_4_spatial_6_4_4_to_5_5_5" width="0.006" rgba="1 0 1 1" stiffness="1" damping="0">
      <site site="site_6_4_4"/>
      <site site="site_5_5_5"/>
    </spatial>
    <spatial name="voxel_5_5_4_spatial_5_5_4_to_6_6_5" width="0.006" rgba="1 0 0 1" stiffness="1" damping="0">
      <site site="site_5_5_4"/>
      <site site="site_6_6_5"/>
    </spatial>
    <spatial name="voxel_5_5_4_spatial_6_6_4_to_5_5_5" width="0.006" rgba="0 1 0 1" stiffness="1" damping="0">
      <site site="site_6_6_4"/>
      <site site="site_5_5_5"/>
    </spatial>
    <spatial name="voxel_5_5_4_spatial_5_6_4_to_6_5_5" width="0.006" rgba="0 0 1 1" stiffness="1" damping="0">
      <site site="site_5_6_4"/>
      <site site="site_6_5_5"/>
    </spatial>
    <spatial name="voxel_5_5_4_spatial_6_5_4_to_5_6_5" width="0.006" rgba="1 0 1 1" stiffness="1" damping="0">
      <site site="site_6_5_4"/>
      <site site="site_5_6_5"/>
    </spatial>
    <spatial name="voxel_6_4_4_spatial_6_4_4_to_7_5_5" width="0.006" rgba="1 0 0 1" stiffness="1" damping="0">
      <site site="site_6_4_4"/>
      <site site="site_7_5_5"/>
    </spatial>
    <spatial name="voxel_6_4_4_spatial_7_5_4_to_6_4_5" width="0.006" rgba="0 1 0 1" stiffness="1" damping="0">
      <site site="site_7_5_4"/>
      <site site="site_6_4_5"/>
    </spatial>
    <spatial name="voxel_6_4_4_spatial_6_5_4_to_7_4_5" width="0.006" rgba="0 0 1 1" stiffness="1" damping="0">
      <site site="site_6_5_4"/>
      <site site="site_7_4_5"/>
    </spatial>
    <spatial name="voxel_6_4_4_spatial_7_4_4_to_6_5_5" width="0.006" rgba="1 0 1 1" stiffness="1" damping="0">
      <site site="site_7_4_4"/>
      <site site="site_6_5_5"/>
    </spatial>
    <spatial name="voxel_6_5_4_spatial_6_5_4_to_7_6_5" width="0.006" rgba="1 0 0 1" stiffness="1" damping="0">
      <site site="site_6_5_4"/>
      <site site="site_7_6_5"/>
    </spatial>
    <spatial name="voxel_6_5_4_spatial_7_6_4_to_6_5_5" width="0.006" rgba="0 1 0 1" stiffness="1" damping="0">
      <site site="site_7_6_4"/>
      <site site="site_6_5_5"/>
    </spatial>
    <spatial name="voxel_6_5_4_spatial_6_6_4_to_7_5_5" width="0.006" rgba="0 0 1 1" stiffness="1" damping="0">
      <site site="site_6_6_4"/>
      <site site="site_7_5_5"/>
    </spatial>
    <spatial name="voxel_6_5_4_spatial_7_5_4_to_6_6_5" width="0.006" rgba="1 0 1 1" stiffness="1" damping="0">
      <site site="site_7_5_4"/>
      <site site="site_6_6_5"/>
    </spatial>
    <spatial name="voxel_7_4_4_spatial_7_4_4_to_8_5_5" width="0.006" rgba="1 0 0 1" stiffness="1" damping="0">
      <site site="site_7_4_4"/>
      <site site="site_8_5_5"/>
    </spatial>
    <spatial name="voxel_7_4_4_spatial_8_5_4_to_7_4_5" width="0.006" rgba="0 1 0 1" stiffness="1" damping="0">
      <site site="site_8_5_4"/>
      <site site="site_7_4_5"/>
    </spatial>
    <spatial name="voxel_7_4_4_spatial_7_5_4_to_8_4_5" width="0.006" rgba="0 0 1 1" stiffness="1" damping="0">
      <site site="site_7_5_4"/>
      <site site="site_8_4_5"/>
    </spatial>
    <spatial name="voxel_7_4_4_spatial_8_4_4_to_7_5_5" width="0.006" rgba="1 0 1 1" stiffness="1" damping="0">
      <site site="site_8_4_4"/>
      <site site="site_7_5_5"/>
    </spatial>
    <spatial name="voxel_7_5_4_spatial_7_5_4_to_8_6_5" width="0.006" rgba="1 0 0 1" stiffness="1" damping="0">
      <site site="site_7_5_4"/>
      <site site="site_8_6_5"/>
    </spatial>
    <spatial name="voxel_7_5_4_spatial_8_6_4_to_7_5_5" width="0.006" rgba="0 1 0 1" stiffness="1" damping="0">
      <site site="site_8_6_4"/>
      <site site="site_7_5_5"/>
    </spatial>
    <spatial name="voxel_7_5_4_spatial_7_6_4_to_8_5_5" width="0.006" rgba="0 0 1 1" stiffness="1" damping="0">
      <site site="site_7_6_4"/>
      <site site="site_8_5_5"/>
    </spatial>
    <spatial name="voxel_7_5_4_spatial_8_5_4_to_7_6_5" width="0.006" rgba="1 0 1 1" stiffness="1" damping="0">
      <site site="site_8_5_4"/>
      <site site="site_7_6_5"/>
    </spatial>
  </tendon>
  <actuator>
    <motor name="voxel_4_4_4_motor_4_4_4_to_5_5_5" tendon="voxel_4_4_4_spatial_4_4_4_to_5_5_5" ctrlrange="0 1" gear="87.63560920082658"/>
    <motor name="voxel_4_4_4_motor_5_5_4_to_4_4_5" tendon="voxel_4_4_4_spatial_5_5_4_to_4_4_5" ctrlrange="0 1" gear="87.63560920082658"/>
    <motor name="voxel_4_4_4_motor_4_5_4_to_5_4_5" tendon="voxel_4_4_4_spatial_4_5_4_to_5_4_5" ctrlrange="0 1" gear="87.63560920082658"/>
    <motor name="voxel_4_4_4_motor_5_4_4_to_4_5_5" tendon="voxel_4_4_4_spatial_5_4_4_to_4_5_5" ctrlrange="0 1" gear="87.63560920082658"/>
    <motor name="voxel_4_5_4_motor_4_5_4_to_5_6_5" tendon="voxel_4_5_4_spatial_4_5_4_to_5_6_5" ctrlrange="0 1" gear="87.63560920082658"/>
    <motor name="voxel_4_5_4_motor_5_6_4_to_4_5_5" tendon="voxel_4_5_4_spatial_5_6_4_to_4_5_5" ctrlrange="0 1" gear="87.63560920082658"/>
    <motor name="voxel_4_5_4_motor_4_6_4_to_5_5_5" tendon="voxel_4_5_4_spatial_4_6_4_to_5_5_5" ctrlrange="0 1" gear="87.63560920082658"/>
    <motor name="voxel_4_5_4_motor_5_5_4_to_4_6_5" tendon="voxel_4_5_4_spatial_5_5_4_to_4_6_5" ctrlrange="0 1" gear="87.63560920082658"/>
    <motor name="voxel_5_4_4_motor_5_4_4_to_6_5_5" tendon="voxel_5_4_4_spatial_5_4_4_to_6_5_5" ctrlrange="0 1" gear="87.63560920082658"/>
    <motor name="voxel_5_4_4_motor_6_5_4_to_5_4_5" tendon="voxel_5_4_4_spatial_6_5_4_to_5_4_5" ctrlrange="0 1" gear="87.63560920082658"/>
    <motor name="voxel_5_4_4_motor_5_5_4_to_6_4_5" tendon="voxel_5_4_4_spatial_5_5_4_to_6_4_5" ctrlrange="0 1" gear="87.63560920082658"/>
    <motor name="voxel_5_4_4_motor_6_4_4_to_5_5_5" tendon="voxel_5_4_4_spatial_6_4_4_to_5_5_5" ctrlrange="0 1" gear="87.63560920082658"/>
    <motor name="voxel_5_5_4_motor_5_5_4_to_6_6_5" tendon="voxel_5_5_4_spatial_5_5_4_to_6_6_5" ctrlrange="0 1" gear="87.63560920082658"/>
    <motor name="voxel_5_5_4_motor_6_6_4_to_5_5_5" tendon="voxel_5_5_4_spatial_6_6_4_to_5_5_5" ctrlrange="0 1" gear="87.63560920082658"/>
    <motor name="voxel_5_5_4_motor_5_6_4_to_6_5_5" tendon="voxel_5_5_4_spatial_5_6_4_to_6_5_5" ctrlrange="0 1" gear="87.63560920082658"/>
    <motor name="voxel_5_5_4_motor_6_5_4_to_5_6_5" tendon="voxel_5_5_4_spatial_6_5_4_to_5_6_5" ctrlrange="0 1" gear="87.63560920082658"/>
    <motor name="voxel_6_4_4_motor_6_4_4_to_7_5_5" tendon="voxel_6_4_4_spatial_6_4_4_to_7_5_5" ctrlrange="0 1" gear="87.63560920082658"/>
    <motor name="voxel_6_4_4_motor_7_5_4_to_6_4_5" tendon="voxel_6_4_4_spatial_7_5_4_to_6_4_5" ctrlrange="0 1" gear="87.63560920082658"/>
    <motor name="voxel_6_4_4_motor_6_5_4_to_7_4_5" tendon="voxel_6_4_4_spatial_6_5_4_to_7_4_5" ctrlrange="0 1" gear="87.63560920082658"/>
    <motor name="voxel_6_4_4_motor_7_4_4_to_6_5_5" tendon="voxel_6_4_4_spatial_7_4_4_to_6_5_5" ctrlrange="0 1" gear="87.63560920082658"/>
    <motor name="voxel_6_5_4_motor_6_5_4_to_7_6_5" tendon="voxel_6_5_4_spatial_6_5_4_to_7_6_5" ctrlrange="0 1" gear="87.63560920082658"/>
    <motor name="voxel_6_5_4_motor_7_6_4_to_6_5_5" tendon="voxel_6_5_4_spatial_7_6_4_to_6_5_5" ctrlrange="0 1" gear="87.63560920082658"/>
    <motor name="voxel_6_5_4_motor_6_6_4_to_7_5_5" tendon="voxel_6_5_4_spatial_6_6_4_to_7_5_5" ctrlrange="0 1" gear="87.63560920082658"/>
    <motor name="voxel_6_5_4_motor_7_5_4_to_6_6_5" tendon="voxel_6_5_4_spatial_7_5_4_to_6_6_5" ctrlrange="0 1" gear="87.63560920082658"/>
    <motor name="voxel_7_4_4_motor_7_4_4_to_8_5_5" tendon="voxel_7_4_4_spatial_7_4_4_to_8_5_5" ctrlrange="0 1" gear="87.63560920082658"/>
    <motor name="voxel_7_4_4_motor_8_5_4_to_7_4_5" tendon="voxel_7_4_4_spatial_8_5_4_to_7_4_5" ctrlrange="0 1" gear="87.63560920082658"/>
    <motor name="voxel_7_4_4_motor_7_5_4_to_8_4_5" tendon="voxel_7_4_4_spatial_7_5_4_to_8_4_5" ctrlrange="0 1" gear="87.63560920082658"/>
    <motor name="voxel_7_4_4_motor_8_4_4_to_7_5_5" tendon="voxel_7_4_4_spatial_8_4_4_to_7_5_5" ctrlrange="0 1" gear="87.63560920082658"/>
    <motor name="voxel_7_5_4_motor_7_5_4_to_8_6_5" tendon="voxel_7_5_4_spatial_7_5_4_to_8_6_5" ctrlrange="0 1" gear="87.63560920082658"/>
    <motor name="voxel_7_5_4_motor_8_6_4_to_7_5_5" tendon="voxel_7_5_4_spatial_8_6_4_to_7_5_5" ctrlrange="0 1" gear="87.63560920082658"/>
    <motor name="voxel_7_5_4_motor_7_6_4_to_8_5_5" tendon="voxel_7_5_4_spatial_7_6_4_to_8_5_5" ctrlrange="0 1" gear="87.63560920082658"/>
    <motor name="voxel_7_5_4_motor_8_5_4_to_7_6_5" tendon="voxel_7_5_4_spatial_8_5_4_to_7_6_5" ctrlrange="0 1" gear="87.63560920082658"/>
  </actuator>
</mujoco>