<?xml version='1.0' encoding='utf-8'?>
<mujoco model="MuJoCo Model">
  <compiler angle="radian" meshdir="asset/" texturedir="asset/" />

  <option timestep="0.001" tolerance="1e-06" integrator="implicitfast" />

  <size memory="2000M" />

  <visual>
    <map stiffness="700" fogstart="1" fogend="15" zfar="40" haze="1" shadowscale="0.5" />
    <rgba haze="0.15 0.25 0.35 1" />
  </visual>

  <statistic meansize="0.05" />

  <asset>
    <texture type="skybox" builtin="gradient" rgb1="0.3 0.5 0.7" rgb2="0 0 0" width="512" height="3072" />
    <texture type="2d" name="texplane" builtin="checker" mark="cross" rgb1="0.2 0.3 0.4" rgb2="0.1 0.15 0.2" markrgb="0.8 0.8 0.8" width="512" height="512" />
    <material name="matplane" texture="texplane" texuniform="true" texrepeat="10 10" reflectance="0.3" />
  </asset>

  <worldbody>
    <geom name="ground" size="0 0 1" type="plane" condim="1" material="matplane" />
    <light pos="30 30 20" dir="0 0 -1" diffuse="0.4 0.4 0.4" specular="0.1 0.1 0.1" />
    <light pos="-20 -20 40" dir="0.0990148 0.0990148 -0.990148" directional="true" diffuse="0.8 0.8 0.8" specular="0.2 0.2 0.2" />
    <body name="vsr_0">
      <inertial pos="0 0 0" mass="1.66667" diaginertia="2.77778e-05 2.77778e-05 2.77778e-05" />
      <joint pos="0 0 0" axis="1 0 0" type="slide" name="vsr_0_x" />
      <joint pos="0 0 0" axis="0 1 0" type="slide" name="vsr_0_y" />
      <joint pos="0 0 0" axis="0 0 1" type="slide" name="vsr_0_z" />
    </body>
    <body name="vsr_1" pos="0 0 1">
      <inertial pos="0 0 0" mass="1.66667" diaginertia="2.77778e-05 2.77778e-05 2.77778e-05" />
      <joint pos="0 0 0" axis="1 0 0" type="slide" name="vsr_1_x" />
      <joint pos="0 0 0" axis="0 1 0" type="slide" name="vsr_1_y" />
      <joint pos="0 0 0" axis="0 0 1" type="slide" name="vsr_1_z" />
    </body>
    <body name="vsr_2" pos="0 1 0">
      <inertial pos="0 0 0" mass="1.66667" diaginertia="2.77778e-05 2.77778e-05 2.77778e-05" />
      <joint pos="0 0 0" axis="1 0 0" type="slide" name="vsr_2_x" />
      <joint pos="0 0 0" axis="0 1 0" type="slide" name="vsr_2_y" />
      <joint pos="0 0 0" axis="0 0 1" type="slide" name="vsr_2_z" />
    </body>
    <body name="vsr_3" pos="0 1 1">
      <inertial pos="0 0 0" mass="1.66667" diaginertia="2.77778e-05 2.77778e-05 2.77778e-05" />
      <joint pos="0 0 0" axis="1 0 0" type="slide" name="vsr_3_x" />
      <joint pos="0 0 0" axis="0 1 0" type="slide" name="vsr_3_y" />
      <joint pos="0 0 0" axis="0 0 1" type="slide" name="vsr_3_z" />
    </body>
    <body name="vsr_4" pos="1 0 0">
      <inertial pos="0 0 0" mass="1.66667" diaginertia="2.77778e-05 2.77778e-05 2.77778e-05" />
      <joint pos="0 0 0" axis="1 0 0" type="slide" name="vsr_4_x" />
      <joint pos="0 0 0" axis="0 1 0" type="slide" name="vsr_4_y" />
      <joint pos="0 0 0" axis="0 0 1" type="slide" name="vsr_4_z" />
    </body>
    <body name="vsr_5" pos="1 0 1">
      <inertial pos="0 0 0" mass="1.66667" diaginertia="2.77778e-05 2.77778e-05 2.77778e-05" />
      <joint pos="0 0 0" axis="1 0 0" type="slide" name="vsr_5_x" />
      <joint pos="0 0 0" axis="0 1 0" type="slide" name="vsr_5_y" />
      <joint pos="0 0 0" axis="0 0 1" type="slide" name="vsr_5_z" />
    </body>
    <body name="vsr_6" pos="1 1 0">
      <inertial pos="0 0 0" mass="1.66667" diaginertia="2.77778e-05 2.77778e-05 2.77778e-05" />
      <joint pos="0 0 0" axis="1 0 0" type="slide" name="vsr_6_x" />
      <joint pos="0 0 0" axis="0 1 0" type="slide" name="vsr_6_y" />
      <joint pos="0 0 0" axis="0 0 1" type="slide" name="vsr_6_z" />
    </body>
    <body name="vsr_7" pos="1 1 1">
      <inertial pos="0 0 0" mass="1.66667" diaginertia="2.77778e-05 2.77778e-05 2.77778e-05" />
      <joint pos="0 0 0" axis="1 0 0" type="slide" name="vsr_7_x" />
      <joint pos="0 0 0" axis="0 1 0" type="slide" name="vsr_7_y" />
      <joint pos="0 0 0" axis="0 0 1" type="slide" name="vsr_7_z" />
    </body>
    <body name="vsr_8" pos="2 0 0">
      <inertial pos="0 0 0" mass="1.66667" diaginertia="2.77778e-05 2.77778e-05 2.77778e-05" />
      <joint pos="0 0 0" axis="1 0 0" type="slide" name="vsr_8_x" />
      <joint pos="0 0 0" axis="0 1 0" type="slide" name="vsr_8_y" />
      <joint pos="0 0 0" axis="0 0 1" type="slide" name="vsr_8_z" />
    </body>
    <body name="vsr_9" pos="2 0 1">
      <inertial pos="0 0 0" mass="1.66667" diaginertia="2.77778e-05 2.77778e-05 2.77778e-05" />
      <joint pos="0 0 0" axis="1 0 0" type="slide" name="vsr_9_x" />
      <joint pos="0 0 0" axis="0 1 0" type="slide" name="vsr_9_y" />
      <joint pos="0 0 0" axis="0 0 1" type="slide" name="vsr_9_z" />
    </body>
    <body name="vsr_10" pos="2 1 0">
      <inertial pos="0 0 0" mass="1.66667" diaginertia="2.77778e-05 2.77778e-05 2.77778e-05" />
      <joint pos="0 0 0" axis="1 0 0" type="slide" name="vsr_10_x" />
      <joint pos="0 0 0" axis="0 1 0" type="slide" name="vsr_10_y" />
      <joint pos="0 0 0" axis="0 0 1" type="slide" name="vsr_10_z" />
    </body>
    <body name="vsr_11" pos="2 1 1">
      <inertial pos="0 0 0" mass="1.66667" diaginertia="2.77778e-05 2.77778e-05 2.77778e-05" />
      <joint pos="0 0 0" axis="1 0 0" type="slide" name="vsr_11_x" />
      <joint pos="0 0 0" axis="0 1 0" type="slide" name="vsr_11_y" />
      <joint pos="0 0 0" axis="0 0 1" type="slide" name="vsr_11_z" />
    </body>
  </worldbody>

  <deformable>
    <flex name="vsr" rgba="0.1 0.9 0.1 1" dim="3" body="vsr_0 vsr_1 vsr_2 vsr_3 vsr_4 vsr_5 vsr_6 vsr_7 vsr_8 vsr_9 vsr_10 vsr_11" element="0 3 2 7 0 1 3 7 0 5 1 7 0 4 5 7 0 6 4 7 0 2 6 7 4 7 6 11 4 5 7 11 4 9 5 11 4 8 9 11 4 10 8 11 4 6 10 11">

      <contact solref="0.01 1" solimp="0.95 0.99 0.0001 0.5 2" selfcollide="none" />
      <elasticity young="500" poisson="0.3" />
      <edge damping="1" />
    </flex>
  </deformable>
<actuator><motor name="vsr_0_x_motor" joint="vsr_0_x" gear="1" /><motor name="vsr_0_y_motor" joint="vsr_0_y" gear="1" /><motor name="vsr_0_z_motor" joint="vsr_0_z" gear="1" /><motor name="vsr_1_x_motor" joint="vsr_1_x" gear="1" /><motor name="vsr_1_y_motor" joint="vsr_1_y" gear="1" /><motor name="vsr_1_z_motor" joint="vsr_1_z" gear="1" /><motor name="vsr_2_x_motor" joint="vsr_2_x" gear="1" /><motor name="vsr_2_y_motor" joint="vsr_2_y" gear="1" /><motor name="vsr_2_z_motor" joint="vsr_2_z" gear="1" /><motor name="vsr_3_x_motor" joint="vsr_3_x" gear="1" /><motor name="vsr_3_y_motor" joint="vsr_3_y" gear="1" /><motor name="vsr_3_z_motor" joint="vsr_3_z" gear="1" /><motor name="vsr_4_x_motor" joint="vsr_4_x" gear="1" /><motor name="vsr_4_y_motor" joint="vsr_4_y" gear="1" /><motor name="vsr_4_z_motor" joint="vsr_4_z" gear="1" /><motor name="vsr_5_x_motor" joint="vsr_5_x" gear="1" /><motor name="vsr_5_y_motor" joint="vsr_5_y" gear="1" /><motor name="vsr_5_z_motor" joint="vsr_5_z" gear="1" /><motor name="vsr_6_x_motor" joint="vsr_6_x" gear="1" /><motor name="vsr_6_y_motor" joint="vsr_6_y" gear="1" /><motor name="vsr_6_z_motor" joint="vsr_6_z" gear="1" /><motor name="vsr_7_x_motor" joint="vsr_7_x" gear="1" /><motor name="vsr_7_y_motor" joint="vsr_7_y" gear="1" /><motor name="vsr_7_z_motor" joint="vsr_7_z" gear="1" /><motor name="vsr_8_x_motor" joint="vsr_8_x" gear="1" /><motor name="vsr_8_y_motor" joint="vsr_8_y" gear="1" /><motor name="vsr_8_z_motor" joint="vsr_8_z" gear="1" /><motor name="vsr_9_x_motor" joint="vsr_9_x" gear="1" /><motor name="vsr_9_y_motor" joint="vsr_9_y" gear="1" /><motor name="vsr_9_z_motor" joint="vsr_9_z" gear="1" /><motor name="vsr_10_x_motor" joint="vsr_10_x" gear="1" /><motor name="vsr_10_y_motor" joint="vsr_10_y" gear="1" /><motor name="vsr_10_z_motor" joint="vsr_10_z" gear="1" /><motor name="vsr_11_x_motor" joint="vsr_11_x" gear="1" /><motor name="vsr_11_y_motor" joint="vsr_11_y" gear="1" /><motor name="vsr_11_z_motor" joint="vsr_11_z" gear="1" /></actuator></mujoco>