<?xml version="1.0" ?>
<mujoco model="MuJoCo Model">
  <compiler angle="radian" meshdir="asset/" texturedir="asset/"/>
  <option timestep="0.001" tolerance="1e-06" integrator="implicitfast"/>
  <size memory="2000M"/>
  <visual>
    <map stiffness="700" fogstart="1" fogend="15" zfar="40" haze="1" shadowscale="0.5"/>
    <rgba haze="0.15 0.25 0.35 1"/>
  </visual>
  <statistic meansize="0.05"/>
  <asset>
    <texture type="skybox" builtin="gradient" rgb1="0.3 0.5 0.7" rgb2="0 0 0" width="512" height="3072"/>
    <texture type="2d" name="texplane" builtin="checker" mark="cross" rgb1="0.2 0.3 0.4" rgb2="0.1 0.15 0.2" markrgb="0.8 0.8 0.8" width="512" height="512"/>
    <material name="matplane" texture="texplane" texuniform="true" texrepeat="10 10" reflectance="0.3"/>
  </asset>
  <worldbody>
    <geom name="ground" size="0 0 1" pos="0 0 -2" type="plane" condim="1" material="matplane"/>
    <light pos="30 30 20" dir="0 0 -1" diffuse="0.4 0.4 0.4" specular="0.1 0.1 0.1"/>
    <light pos="-20 -20 40" dir="0.0990148 0.0990148 -0.990148" directional="true" diffuse="0.8 0.8 0.8" specular="0.2 0.2 0.2"/>
    <body name="target" pos="-300 3 3.5">
      <geom size="1 1 3" type="box" rgba="1 0 0 0.7"/>
      <site name="site_-300_3_3.5" pos="0 0 0" size="0.005"/>
    </body>
    <body name="vsr_0" pos="0 0 0">
      <inertial pos="0 0 0" mass="0.1" diaginertia="1.66667e-06 1.66667e-06 1.66667e-06"/>
      <joint pos="0 0 0" axis="1 0 0" type="slide"/>
      <joint pos="0 0 0" axis="0 1 0" type="slide"/>
      <joint pos="0 0 0" axis="0 0 1" type="slide"/>
      <site name="site_0_0_0" pos="0 0 0" size="0.005"/>
    </body>
    <body name="vsr_1" pos="0 0 1">
      <inertial pos="0 0 0" mass="0.1" diaginertia="1.66667e-06 1.66667e-06 1.66667e-06"/>
      <joint pos="0 0 0" axis="1 0 0" type="slide"/>
      <joint pos="0 0 0" axis="0 1 0" type="slide"/>
      <joint pos="0 0 0" axis="0 0 1" type="slide"/>
      <site name="site_0_0_1" pos="0 0 0" size="0.005"/>
    </body>
    <body name="vsr_2" pos="0 1 0">
      <inertial pos="0 0 0" mass="0.1" diaginertia="1.66667e-06 1.66667e-06 1.66667e-06"/>
      <joint pos="0 0 0" axis="1 0 0" type="slide"/>
      <joint pos="0 0 0" axis="0 1 0" type="slide"/>
      <joint pos="0 0 0" axis="0 0 1" type="slide"/>
      <site name="site_0_1_0" pos="0 0 0" size="0.005"/>
    </body>
    <body name="vsr_3" pos="0 1 1">
      <inertial pos="0 0 0" mass="0.1" diaginertia="1.66667e-06 1.66667e-06 1.66667e-06"/>
      <joint pos="0 0 0" axis="1 0 0" type="slide"/>
      <joint pos="0 0 0" axis="0 1 0" type="slide"/>
      <joint pos="0 0 0" axis="0 0 1" type="slide"/>
      <site name="site_0_1_1" pos="0 0 0" size="0.005"/>
    </body>
    <body name="vsr_4" pos="1 0 0">
      <inertial pos="0 0 0" mass="0.1" diaginertia="1.66667e-06 1.66667e-06 1.66667e-06"/>
      <joint pos="0 0 0" axis="1 0 0" type="slide"/>
      <joint pos="0 0 0" axis="0 1 0" type="slide"/>
      <joint pos="0 0 0" axis="0 0 1" type="slide"/>
      <site name="site_1_0_0" pos="0 0 0" size="0.005"/>
    </body>
    <body name="vsr_5" pos="1 0 1">
      <inertial pos="0 0 0" mass="0.1" diaginertia="1.66667e-06 1.66667e-06 1.66667e-06"/>
      <joint pos="0 0 0" axis="1 0 0" type="slide"/>
      <joint pos="0 0 0" axis="0 1 0" type="slide"/>
      <joint pos="0 0 0" axis="0 0 1" type="slide"/>
      <site name="site_1_0_1" pos="0 0 0" size="0.005"/>
    </body>
    <body name="vsr_6" pos="1 0 2">
      <inertial pos="0 0 0" mass="0.1" diaginertia="1.66667e-06 1.66667e-06 1.66667e-06"/>
      <joint pos="0 0 0" axis="1 0 0" type="slide"/>
      <joint pos="0 0 0" axis="0 1 0" type="slide"/>
      <joint pos="0 0 0" axis="0 0 1" type="slide"/>
      <site name="site_1_0_2" pos="0 0 0" size="0.005"/>
    </body>
    <body name="vsr_7" pos="1 1 0">
      <inertial pos="0 0 0" mass="0.1" diaginertia="1.66667e-06 1.66667e-06 1.66667e-06"/>
      <joint pos="0 0 0" axis="1 0 0" type="slide"/>
      <joint pos="0 0 0" axis="0 1 0" type="slide"/>
      <joint pos="0 0 0" axis="0 0 1" type="slide"/>
      <site name="site_1_1_0" pos="0 0 0" size="0.005"/>
    </body>
    <body name="vsr_8" pos="1 1 1">
      <inertial pos="0 0 0" mass="0.1" diaginertia="1.66667e-06 1.66667e-06 1.66667e-06"/>
      <joint pos="0 0 0" axis="1 0 0" type="slide"/>
      <joint pos="0 0 0" axis="0 1 0" type="slide"/>
      <joint pos="0 0 0" axis="0 0 1" type="slide"/>
      <site name="site_1_1_1" pos="0 0 0" size="0.005"/>
    </body>
    <body name="vsr_9" pos="1 1 2">
      <inertial pos="0 0 0" mass="0.1" diaginertia="1.66667e-06 1.66667e-06 1.66667e-06"/>
      <joint pos="0 0 0" axis="1 0 0" type="slide"/>
      <joint pos="0 0 0" axis="0 1 0" type="slide"/>
      <joint pos="0 0 0" axis="0 0 1" type="slide"/>
      <site name="site_1_1_2" pos="0 0 0" size="0.005"/>
    </body>
    <body name="vsr_10" pos="1 2 0">
      <inertial pos="0 0 0" mass="0.1" diaginertia="1.66667e-06 1.66667e-06 1.66667e-06"/>
      <joint pos="0 0 0" axis="1 0 0" type="slide"/>
      <joint pos="0 0 0" axis="0 1 0" type="slide"/>
      <joint pos="0 0 0" axis="0 0 1" type="slide"/>
      <site name="site_1_2_0" pos="0 0 0" size="0.005"/>
    </body>
    <body name="vsr_11" pos="1 2 1">
      <inertial pos="0 0 0" mass="0.1" diaginertia="1.66667e-06 1.66667e-06 1.66667e-06"/>
      <joint pos="0 0 0" axis="1 0 0" type="slide"/>
      <joint pos="0 0 0" axis="0 1 0" type="slide"/>
      <joint pos="0 0 0" axis="0 0 1" type="slide"/>
      <site name="site_1_2_1" pos="0 0 0" size="0.005"/>
    </body>
    <body name="vsr_12" pos="2 0 0">
      <inertial pos="0 0 0" mass="0.1" diaginertia="1.66667e-06 1.66667e-06 1.66667e-06"/>
      <joint pos="0 0 0" axis="1 0 0" type="slide"/>
      <joint pos="0 0 0" axis="0 1 0" type="slide"/>
      <joint pos="0 0 0" axis="0 0 1" type="slide"/>
      <site name="site_2_0_0" pos="0 0 0" size="0.005"/>
    </body>
    <body name="vsr_13" pos="2 0 1">
      <inertial pos="0 0 0" mass="0.1" diaginertia="1.66667e-06 1.66667e-06 1.66667e-06"/>
      <joint pos="0 0 0" axis="1 0 0" type="slide"/>
      <joint pos="0 0 0" axis="0 1 0" type="slide"/>
      <joint pos="0 0 0" axis="0 0 1" type="slide"/>
      <site name="site_2_0_1" pos="0 0 0" size="0.005"/>
    </body>
    <body name="vsr_14" pos="2 0 2">
      <inertial pos="0 0 0" mass="0.1" diaginertia="1.66667e-06 1.66667e-06 1.66667e-06"/>
      <joint pos="0 0 0" axis="1 0 0" type="slide"/>
      <joint pos="0 0 0" axis="0 1 0" type="slide"/>
      <joint pos="0 0 0" axis="0 0 1" type="slide"/>
      <site name="site_2_0_2" pos="0 0 0" size="0.005"/>
    </body>
    <body name="vsr_15" pos="2 1 0">
      <inertial pos="0 0 0" mass="0.1" diaginertia="1.66667e-06 1.66667e-06 1.66667e-06"/>
      <joint pos="0 0 0" axis="1 0 0" type="slide"/>
      <joint pos="0 0 0" axis="0 1 0" type="slide"/>
      <joint pos="0 0 0" axis="0 0 1" type="slide"/>
      <site name="site_2_1_0" pos="0 0 0" size="0.005"/>
    </body>
    <body name="vsr_16" pos="2 1 1">
      <inertial pos="0 0 0" mass="0.1" diaginertia="1.66667e-06 1.66667e-06 1.66667e-06"/>
      <joint pos="0 0 0" axis="1 0 0" type="slide"/>
      <joint pos="0 0 0" axis="0 1 0" type="slide"/>
      <joint pos="0 0 0" axis="0 0 1" type="slide"/>
      <site name="site_2_1_1" pos="0 0 0" size="0.005"/>
    </body>
    <body name="vsr_17" pos="2 1 2">
      <inertial pos="0 0 0" mass="0.1" diaginertia="1.66667e-06 1.66667e-06 1.66667e-06"/>
      <joint pos="0 0 0" axis="1 0 0" type="slide"/>
      <joint pos="0 0 0" axis="0 1 0" type="slide"/>
      <joint pos="0 0 0" axis="0 0 1" type="slide"/>
      <site name="site_2_1_2" pos="0 0 0" size="0.005"/>
    </body>
    <body name="vsr_18" pos="2 2 0">
      <inertial pos="0 0 0" mass="0.1" diaginertia="1.66667e-06 1.66667e-06 1.66667e-06"/>
      <joint pos="0 0 0" axis="1 0 0" type="slide"/>
      <joint pos="0 0 0" axis="0 1 0" type="slide"/>
      <joint pos="0 0 0" axis="0 0 1" type="slide"/>
      <site name="site_2_2_0" pos="0 0 0" size="0.005"/>
    </body>
    <body name="vsr_19" pos="2 2 1">
      <inertial pos="0 0 0" mass="0.1" diaginertia="1.66667e-06 1.66667e-06 1.66667e-06"/>
      <joint pos="0 0 0" axis="1 0 0" type="slide"/>
      <joint pos="0 0 0" axis="0 1 0" type="slide"/>
      <joint pos="0 0 0" axis="0 0 1" type="slide"/>
      <site name="site_2_2_1" pos="0 0 0" size="0.005"/>
    </body>
    <body name="vsr_20" pos="3 0 0">
      <inertial pos="0 0 0" mass="0.1" diaginertia="1.66667e-06 1.66667e-06 1.66667e-06"/>
      <joint pos="0 0 0" axis="1 0 0" type="slide"/>
      <joint pos="0 0 0" axis="0 1 0" type="slide"/>
      <joint pos="0 0 0" axis="0 0 1" type="slide"/>
      <site name="site_3_0_0" pos="0 0 0" size="0.005"/>
    </body>
    <body name="vsr_21" pos="3 0 1">
      <inertial pos="0 0 0" mass="0.1" diaginertia="1.66667e-06 1.66667e-06 1.66667e-06"/>
      <joint pos="0 0 0" axis="1 0 0" type="slide"/>
      <joint pos="0 0 0" axis="0 1 0" type="slide"/>
      <joint pos="0 0 0" axis="0 0 1" type="slide"/>
      <site name="site_3_0_1" pos="0 0 0" size="0.005"/>
    </body>
    <body name="vsr_22" pos="3 1 0">
      <inertial pos="0 0 0" mass="0.1" diaginertia="1.66667e-06 1.66667e-06 1.66667e-06"/>
      <joint pos="0 0 0" axis="1 0 0" type="slide"/>
      <joint pos="0 0 0" axis="0 1 0" type="slide"/>
      <joint pos="0 0 0" axis="0 0 1" type="slide"/>
      <site name="site_3_1_0" pos="0 0 0" size="0.005"/>
    </body>
    <body name="vsr_23" pos="3 1 1">
      <inertial pos="0 0 0" mass="0.1" diaginertia="1.66667e-06 1.66667e-06 1.66667e-06"/>
      <joint pos="0 0 0" axis="1 0 0" type="slide"/>
      <joint pos="0 0 0" axis="0 1 0" type="slide"/>
      <joint pos="0 0 0" axis="0 0 1" type="slide"/>
      <site name="site_3_1_1" pos="0 0 0" size="0.005"/>
    </body>
  </worldbody>
  <deformable>
    <flex name="vsr" rgba="0.1 0.9 0.1 1" dim="3" body="vsr_0 vsr_1 vsr_2 vsr_3 vsr_4 vsr_5 vsr_6 vsr_7 vsr_8 vsr_9 vsr_10 vsr_11 vsr_12 vsr_13 vsr_14 vsr_15 vsr_16 vsr_17 vsr_18 vsr_19 vsr_20 vsr_21 vsr_22 vsr_23" element="0 3 2 8 0 1 3 8 0 5 1 8 0 4 5 8 0 7 4 8 0 2 7 8 4 8 7 16 4 5 8 16 4 13 5 16 4 12 13 16 4 15 12 16 4 7 15 16 5 9 8 17 5 6 9 17 5 14 6 17 5 13 14 17 5 16 13 17 5 8 16 17 7 11 10 19 7 8 11 19 7 16 8 19 7 15 16 19 7 18 15 19 7 10 18 19 12 16 15 23 12 13 16 23 12 21 13 23 12 20 21 23 12 22 20 23 12 15 22 23">
      <contact solref="0.01 1" solimp="0.95 0.99 0.0001 0.5 2" selfcollide="none"/>
      <elasticity young="250" poisson="0.3"/>
      <edge damping="1"/>
    </flex>
  </deformable>
  <tendon>
    <spatial name="voxel_0_0_0_spatial_0_0_0_to_1_1_1" width="0.006" rgba="1 0 0 1" stiffness="1" damping="0">
      <site site="site_0_0_0"/>
      <site site="site_1_1_1"/>
    </spatial>
    <spatial name="voxel_0_0_0_spatial_1_1_0_to_0_0_1" width="0.006" rgba="0 1 0 1" stiffness="1" damping="0">
      <site site="site_1_1_0"/>
      <site site="site_0_0_1"/>
    </spatial>
    <spatial name="voxel_0_0_0_spatial_0_1_0_to_1_0_1" width="0.006" rgba="0 0 1 1" stiffness="1" damping="0">
      <site site="site_0_1_0"/>
      <site site="site_1_0_1"/>
    </spatial>
    <spatial name="voxel_0_0_0_spatial_1_0_0_to_0_1_1" width="0.006" rgba="1 0 1 1" stiffness="1" damping="0">
      <site site="site_1_0_0"/>
      <site site="site_0_1_1"/>
    </spatial>
    <spatial name="voxel_1_0_0_spatial_1_0_0_to_2_1_1" width="0.006" rgba="1 0 0 1" stiffness="1" damping="0">
      <site site="site_1_0_0"/>
      <site site="site_2_1_1"/>
    </spatial>
    <spatial name="voxel_1_0_0_spatial_2_1_0_to_1_0_1" width="0.006" rgba="0 1 0 1" stiffness="1" damping="0">
      <site site="site_2_1_0"/>
      <site site="site_1_0_1"/>
    </spatial>
    <spatial name="voxel_1_0_0_spatial_1_1_0_to_2_0_1" width="0.006" rgba="0 0 1 1" stiffness="1" damping="0">
      <site site="site_1_1_0"/>
      <site site="site_2_0_1"/>
    </spatial>
    <spatial name="voxel_1_0_0_spatial_2_0_0_to_1_1_1" width="0.006" rgba="1 0 1 1" stiffness="1" damping="0">
      <site site="site_2_0_0"/>
      <site site="site_1_1_1"/>
    </spatial>
    <spatial name="voxel_1_0_1_spatial_1_0_1_to_2_1_2" width="0.006" rgba="1 0 0 1" stiffness="1" damping="0">
      <site site="site_1_0_1"/>
      <site site="site_2_1_2"/>
    </spatial>
    <spatial name="voxel_1_0_1_spatial_2_1_1_to_1_0_2" width="0.006" rgba="0 1 0 1" stiffness="1" damping="0">
      <site site="site_2_1_1"/>
      <site site="site_1_0_2"/>
    </spatial>
    <spatial name="voxel_1_0_1_spatial_1_1_1_to_2_0_2" width="0.006" rgba="0 0 1 1" stiffness="1" damping="0">
      <site site="site_1_1_1"/>
      <site site="site_2_0_2"/>
    </spatial>
    <spatial name="voxel_1_0_1_spatial_2_0_1_to_1_1_2" width="0.006" rgba="1 0 1 1" stiffness="1" damping="0">
      <site site="site_2_0_1"/>
      <site site="site_1_1_2"/>
    </spatial>
    <spatial name="voxel_1_1_0_spatial_1_1_0_to_2_2_1" width="0.006" rgba="1 0 0 1" stiffness="1" damping="0">
      <site site="site_1_1_0"/>
      <site site="site_2_2_1"/>
    </spatial>
    <spatial name="voxel_1_1_0_spatial_2_2_0_to_1_1_1" width="0.006" rgba="0 1 0 1" stiffness="1" damping="0">
      <site site="site_2_2_0"/>
      <site site="site_1_1_1"/>
    </spatial>
    <spatial name="voxel_1_1_0_spatial_1_2_0_to_2_1_1" width="0.006" rgba="0 0 1 1" stiffness="1" damping="0">
      <site site="site_1_2_0"/>
      <site site="site_2_1_1"/>
    </spatial>
    <spatial name="voxel_1_1_0_spatial_2_1_0_to_1_2_1" width="0.006" rgba="1 0 1 1" stiffness="1" damping="0">
      <site site="site_2_1_0"/>
      <site site="site_1_2_1"/>
    </spatial>
    <spatial name="voxel_2_0_0_spatial_2_0_0_to_3_1_1" width="0.006" rgba="1 0 0 1" stiffness="1" damping="0">
      <site site="site_2_0_0"/>
      <site site="site_3_1_1"/>
    </spatial>
    <spatial name="voxel_2_0_0_spatial_3_1_0_to_2_0_1" width="0.006" rgba="0 1 0 1" stiffness="1" damping="0">
      <site site="site_3_1_0"/>
      <site site="site_2_0_1"/>
    </spatial>
    <spatial name="voxel_2_0_0_spatial_2_1_0_to_3_0_1" width="0.006" rgba="0 0 1 1" stiffness="1" damping="0">
      <site site="site_2_1_0"/>
      <site site="site_3_0_1"/>
    </spatial>
    <spatial name="voxel_2_0_0_spatial_3_0_0_to_2_1_1" width="0.006" rgba="1 0 1 1" stiffness="1" damping="0">
      <site site="site_3_0_0"/>
      <site site="site_2_1_1"/>
    </spatial>
  </tendon>
  <actuator>
    <motor name="voxel_0_0_0_motor_0_0_0_to_1_1_1" tendon="voxel_0_0_0_spatial_0_0_0_to_1_1_1" ctrlrange="0 1" gear="100.0"/>
    <motor name="voxel_0_0_0_motor_1_1_0_to_0_0_1" tendon="voxel_0_0_0_spatial_1_1_0_to_0_0_1" ctrlrange="0 1" gear="100.0"/>
    <motor name="voxel_0_0_0_motor_0_1_0_to_1_0_1" tendon="voxel_0_0_0_spatial_0_1_0_to_1_0_1" ctrlrange="0 1" gear="100.0"/>
    <motor name="voxel_0_0_0_motor_1_0_0_to_0_1_1" tendon="voxel_0_0_0_spatial_1_0_0_to_0_1_1" ctrlrange="0 1" gear="100.0"/>
    <motor name="voxel_1_0_0_motor_1_0_0_to_2_1_1" tendon="voxel_1_0_0_spatial_1_0_0_to_2_1_1" ctrlrange="0 1" gear="100.0"/>
    <motor name="voxel_1_0_0_motor_2_1_0_to_1_0_1" tendon="voxel_1_0_0_spatial_2_1_0_to_1_0_1" ctrlrange="0 1" gear="100.0"/>
    <motor name="voxel_1_0_0_motor_1_1_0_to_2_0_1" tendon="voxel_1_0_0_spatial_1_1_0_to_2_0_1" ctrlrange="0 1" gear="100.0"/>
    <motor name="voxel_1_0_0_motor_2_0_0_to_1_1_1" tendon="voxel_1_0_0_spatial_2_0_0_to_1_1_1" ctrlrange="0 1" gear="100.0"/>
    <motor name="voxel_1_0_1_motor_1_0_1_to_2_1_2" tendon="voxel_1_0_1_spatial_1_0_1_to_2_1_2" ctrlrange="0 1" gear="100.0"/>
    <motor name="voxel_1_0_1_motor_2_1_1_to_1_0_2" tendon="voxel_1_0_1_spatial_2_1_1_to_1_0_2" ctrlrange="0 1" gear="100.0"/>
    <motor name="voxel_1_0_1_motor_1_1_1_to_2_0_2" tendon="voxel_1_0_1_spatial_1_1_1_to_2_0_2" ctrlrange="0 1" gear="100.0"/>
    <motor name="voxel_1_0_1_motor_2_0_1_to_1_1_2" tendon="voxel_1_0_1_spatial_2_0_1_to_1_1_2" ctrlrange="0 1" gear="100.0"/>
    <motor name="voxel_1_1_0_motor_1_1_0_to_2_2_1" tendon="voxel_1_1_0_spatial_1_1_0_to_2_2_1" ctrlrange="0 1" gear="100.0"/>
    <motor name="voxel_1_1_0_motor_2_2_0_to_1_1_1" tendon="voxel_1_1_0_spatial_2_2_0_to_1_1_1" ctrlrange="0 1" gear="100.0"/>
    <motor name="voxel_1_1_0_motor_1_2_0_to_2_1_1" tendon="voxel_1_1_0_spatial_1_2_0_to_2_1_1" ctrlrange="0 1" gear="100.0"/>
    <motor name="voxel_1_1_0_motor_2_1_0_to_1_2_1" tendon="voxel_1_1_0_spatial_2_1_0_to_1_2_1" ctrlrange="0 1" gear="100.0"/>
    <motor name="voxel_2_0_0_motor_2_0_0_to_3_1_1" tendon="voxel_2_0_0_spatial_2_0_0_to_3_1_1" ctrlrange="0 1" gear="100.0"/>
    <motor name="voxel_2_0_0_motor_3_1_0_to_2_0_1" tendon="voxel_2_0_0_spatial_3_1_0_to_2_0_1" ctrlrange="0 1" gear="100.0"/>
    <motor name="voxel_2_0_0_motor_2_1_0_to_3_0_1" tendon="voxel_2_0_0_spatial_2_1_0_to_3_0_1" ctrlrange="0 1" gear="100.0"/>
    <motor name="voxel_2_0_0_motor_3_0_0_to_2_1_1" tendon="voxel_2_0_0_spatial_3_0_0_to_2_1_1" ctrlrange="0 1" gear="100.0"/>
  </actuator>
</mujoco>