<?xml version="1.0" ?>
<mujoco model="MuJoCo Model">
  <compiler angle="radian" meshdir="asset/" texturedir="asset/"/>
  <option timestep="0.001" tolerance="1e-06" integrator="implicitfast"/>
  <size memory="2000M"/>
  <visual>
    <map stiffness="700" fogstart="1" fogend="15" zfar="40" haze="1" shadowscale="0.5"/>
    <rgba haze="0.15 0.25 0.35 1"/>
  </visual>
  <statistic meansize="0.05"/>
  <asset>
    <texture type="skybox" builtin="gradient" rgb1="0.3 0.5 0.7" rgb2="0 0 0" width="512" height="3072"/>
    <texture type="2d" name="texplane" builtin="checker" mark="cross" rgb1="0.2 0.3 0.4" rgb2="0.1 0.15 0.2" markrgb="0.8 0.8 0.8" width="512" height="512"/>
    <material name="matplane" texture="texplane" texuniform="true" texrepeat="10 10" reflectance="0.3"/>
  </asset>
  <worldbody>
    <geom name="ground" size="0 0 1" pos="0 0 -2" type="plane" condim="1" material="matplane"/>
    <light pos="30 30 20" dir="0 0 -1" diffuse="0.4 0.4 0.4" specular="0.1 0.1 0.1"/>
    <light pos="-20 -20 40" dir="0.0990148 0.0990148 -0.990148" directional="true" diffuse="0.8 0.8 0.8" specular="0.2 0.2 0.2"/>
    <body name="target" pos="-300 3 3.5">
      <geom size="1 1 3" type="box" rgba="1 0 0 0.7"/>
      <site name="site_-300_3_3.5" pos="0 0 0" size="0.005"/>
    </body>
    <body name="vsr_0" pos="4 4 4">
      <inertial pos="0 0 0" mass="0.1" diaginertia="1.66667e-06 1.66667e-06 1.66667e-06"/>
      <joint pos="0 0 0" axis="1 0 0" type="slide"/>
      <joint pos="0 0 0" axis="0 1 0" type="slide"/>
      <joint pos="0 0 0" axis="0 0 1" type="slide"/>
      <site name="site_4_4_4" pos="0 0 0" size="0.005"/>
    </body>
    <body name="vsr_1" pos="4 4 5">
      <inertial pos="0 0 0" mass="0.1" diaginertia="1.66667e-06 1.66667e-06 1.66667e-06"/>
      <joint pos="0 0 0" axis="1 0 0" type="slide"/>
      <joint pos="0 0 0" axis="0 1 0" type="slide"/>
      <joint pos="0 0 0" axis="0 0 1" type="slide"/>
      <site name="site_4_4_5" pos="0 0 0" size="0.005"/>
    </body>
    <body name="vsr_2" pos="4 5 4">
      <inertial pos="0 0 0" mass="0.1" diaginertia="1.66667e-06 1.66667e-06 1.66667e-06"/>
      <joint pos="0 0 0" axis="1 0 0" type="slide"/>
      <joint pos="0 0 0" axis="0 1 0" type="slide"/>
      <joint pos="0 0 0" axis="0 0 1" type="slide"/>
      <site name="site_4_5_4" pos="0 0 0" size="0.005"/>
    </body>
    <body name="vsr_3" pos="4 5 5">
      <inertial pos="0 0 0" mass="0.1" diaginertia="1.66667e-06 1.66667e-06 1.66667e-06"/>
      <joint pos="0 0 0" axis="1 0 0" type="slide"/>
      <joint pos="0 0 0" axis="0 1 0" type="slide"/>
      <joint pos="0 0 0" axis="0 0 1" type="slide"/>
      <site name="site_4_5_5" pos="0 0 0" size="0.005"/>
    </body>
    <body name="vsr_4" pos="4 5 6">
      <inertial pos="0 0 0" mass="0.1" diaginertia="1.66667e-06 1.66667e-06 1.66667e-06"/>
      <joint pos="0 0 0" axis="1 0 0" type="slide"/>
      <joint pos="0 0 0" axis="0 1 0" type="slide"/>
      <joint pos="0 0 0" axis="0 0 1" type="slide"/>
      <site name="site_4_5_6" pos="0 0 0" size="0.005"/>
    </body>
    <body name="vsr_5" pos="4 6 5">
      <inertial pos="0 0 0" mass="0.1" diaginertia="1.66667e-06 1.66667e-06 1.66667e-06"/>
      <joint pos="0 0 0" axis="1 0 0" type="slide"/>
      <joint pos="0 0 0" axis="0 1 0" type="slide"/>
      <joint pos="0 0 0" axis="0 0 1" type="slide"/>
      <site name="site_4_6_5" pos="0 0 0" size="0.005"/>
    </body>
    <body name="vsr_6" pos="4 6 6">
      <inertial pos="0 0 0" mass="0.1" diaginertia="1.66667e-06 1.66667e-06 1.66667e-06"/>
      <joint pos="0 0 0" axis="1 0 0" type="slide"/>
      <joint pos="0 0 0" axis="0 1 0" type="slide"/>
      <joint pos="0 0 0" axis="0 0 1" type="slide"/>
      <site name="site_4_6_6" pos="0 0 0" size="0.005"/>
    </body>
    <body name="vsr_7" pos="5 4 4">
      <inertial pos="0 0 0" mass="0.1" diaginertia="1.66667e-06 1.66667e-06 1.66667e-06"/>
      <joint pos="0 0 0" axis="1 0 0" type="slide"/>
      <joint pos="0 0 0" axis="0 1 0" type="slide"/>
      <joint pos="0 0 0" axis="0 0 1" type="slide"/>
      <site name="site_5_4_4" pos="0 0 0" size="0.005"/>
    </body>
    <body name="vsr_8" pos="5 4 5">
      <inertial pos="0 0 0" mass="0.1" diaginertia="1.66667e-06 1.66667e-06 1.66667e-06"/>
      <joint pos="0 0 0" axis="1 0 0" type="slide"/>
      <joint pos="0 0 0" axis="0 1 0" type="slide"/>
      <joint pos="0 0 0" axis="0 0 1" type="slide"/>
      <site name="site_5_4_5" pos="0 0 0" size="0.005"/>
    </body>
    <body name="vsr_9" pos="5 4 6">
      <inertial pos="0 0 0" mass="0.1" diaginertia="1.66667e-06 1.66667e-06 1.66667e-06"/>
      <joint pos="0 0 0" axis="1 0 0" type="slide"/>
      <joint pos="0 0 0" axis="0 1 0" type="slide"/>
      <joint pos="0 0 0" axis="0 0 1" type="slide"/>
      <site name="site_5_4_6" pos="0 0 0" size="0.005"/>
    </body>
    <body name="vsr_10" pos="5 5 4">
      <inertial pos="0 0 0" mass="0.1" diaginertia="1.66667e-06 1.66667e-06 1.66667e-06"/>
      <joint pos="0 0 0" axis="1 0 0" type="slide"/>
      <joint pos="0 0 0" axis="0 1 0" type="slide"/>
      <joint pos="0 0 0" axis="0 0 1" type="slide"/>
      <site name="site_5_5_4" pos="0 0 0" size="0.005"/>
    </body>
    <body name="vsr_11" pos="5 5 5">
      <inertial pos="0 0 0" mass="0.1" diaginertia="1.66667e-06 1.66667e-06 1.66667e-06"/>
      <joint pos="0 0 0" axis="1 0 0" type="slide"/>
      <joint pos="0 0 0" axis="0 1 0" type="slide"/>
      <joint pos="0 0 0" axis="0 0 1" type="slide"/>
      <site name="site_5_5_5" pos="0 0 0" size="0.005"/>
    </body>
    <body name="vsr_12" pos="5 5 6">
      <inertial pos="0 0 0" mass="0.1" diaginertia="1.66667e-06 1.66667e-06 1.66667e-06"/>
      <joint pos="0 0 0" axis="1 0 0" type="slide"/>
      <joint pos="0 0 0" axis="0 1 0" type="slide"/>
      <joint pos="0 0 0" axis="0 0 1" type="slide"/>
      <site name="site_5_5_6" pos="0 0 0" size="0.005"/>
    </body>
    <body name="vsr_13" pos="5 6 4">
      <inertial pos="0 0 0" mass="0.1" diaginertia="1.66667e-06 1.66667e-06 1.66667e-06"/>
      <joint pos="0 0 0" axis="1 0 0" type="slide"/>
      <joint pos="0 0 0" axis="0 1 0" type="slide"/>
      <joint pos="0 0 0" axis="0 0 1" type="slide"/>
      <site name="site_5_6_4" pos="0 0 0" size="0.005"/>
    </body>
    <body name="vsr_14" pos="5 6 5">
      <inertial pos="0 0 0" mass="0.1" diaginertia="1.66667e-06 1.66667e-06 1.66667e-06"/>
      <joint pos="0 0 0" axis="1 0 0" type="slide"/>
      <joint pos="0 0 0" axis="0 1 0" type="slide"/>
      <joint pos="0 0 0" axis="0 0 1" type="slide"/>
      <site name="site_5_6_5" pos="0 0 0" size="0.005"/>
    </body>
    <body name="vsr_15" pos="5 6 6">
      <inertial pos="0 0 0" mass="0.1" diaginertia="1.66667e-06 1.66667e-06 1.66667e-06"/>
      <joint pos="0 0 0" axis="1 0 0" type="slide"/>
      <joint pos="0 0 0" axis="0 1 0" type="slide"/>
      <joint pos="0 0 0" axis="0 0 1" type="slide"/>
      <site name="site_5_6_6" pos="0 0 0" size="0.005"/>
    </body>
    <body name="vsr_16" pos="6 4 4">
      <inertial pos="0 0 0" mass="0.1" diaginertia="1.66667e-06 1.66667e-06 1.66667e-06"/>
      <joint pos="0 0 0" axis="1 0 0" type="slide"/>
      <joint pos="0 0 0" axis="0 1 0" type="slide"/>
      <joint pos="0 0 0" axis="0 0 1" type="slide"/>
      <site name="site_6_4_4" pos="0 0 0" size="0.005"/>
    </body>
    <body name="vsr_17" pos="6 4 5">
      <inertial pos="0 0 0" mass="0.1" diaginertia="1.66667e-06 1.66667e-06 1.66667e-06"/>
      <joint pos="0 0 0" axis="1 0 0" type="slide"/>
      <joint pos="0 0 0" axis="0 1 0" type="slide"/>
      <joint pos="0 0 0" axis="0 0 1" type="slide"/>
      <site name="site_6_4_5" pos="0 0 0" size="0.005"/>
    </body>
    <body name="vsr_18" pos="6 4 6">
      <inertial pos="0 0 0" mass="0.1" diaginertia="1.66667e-06 1.66667e-06 1.66667e-06"/>
      <joint pos="0 0 0" axis="1 0 0" type="slide"/>
      <joint pos="0 0 0" axis="0 1 0" type="slide"/>
      <joint pos="0 0 0" axis="0 0 1" type="slide"/>
      <site name="site_6_4_6" pos="0 0 0" size="0.005"/>
    </body>
    <body name="vsr_19" pos="6 5 4">
      <inertial pos="0 0 0" mass="0.1" diaginertia="1.66667e-06 1.66667e-06 1.66667e-06"/>
      <joint pos="0 0 0" axis="1 0 0" type="slide"/>
      <joint pos="0 0 0" axis="0 1 0" type="slide"/>
      <joint pos="0 0 0" axis="0 0 1" type="slide"/>
      <site name="site_6_5_4" pos="0 0 0" size="0.005"/>
    </body>
    <body name="vsr_20" pos="6 5 5">
      <inertial pos="0 0 0" mass="0.1" diaginertia="1.66667e-06 1.66667e-06 1.66667e-06"/>
      <joint pos="0 0 0" axis="1 0 0" type="slide"/>
      <joint pos="0 0 0" axis="0 1 0" type="slide"/>
      <joint pos="0 0 0" axis="0 0 1" type="slide"/>
      <site name="site_6_5_5" pos="0 0 0" size="0.005"/>
    </body>
    <body name="vsr_21" pos="6 5 6">
      <inertial pos="0 0 0" mass="0.1" diaginertia="1.66667e-06 1.66667e-06 1.66667e-06"/>
      <joint pos="0 0 0" axis="1 0 0" type="slide"/>
      <joint pos="0 0 0" axis="0 1 0" type="slide"/>
      <joint pos="0 0 0" axis="0 0 1" type="slide"/>
      <site name="site_6_5_6" pos="0 0 0" size="0.005"/>
    </body>
    <body name="vsr_22" pos="6 6 4">
      <inertial pos="0 0 0" mass="0.1" diaginertia="1.66667e-06 1.66667e-06 1.66667e-06"/>
      <joint pos="0 0 0" axis="1 0 0" type="slide"/>
      <joint pos="0 0 0" axis="0 1 0" type="slide"/>
      <joint pos="0 0 0" axis="0 0 1" type="slide"/>
      <site name="site_6_6_4" pos="0 0 0" size="0.005"/>
    </body>
    <body name="vsr_23" pos="6 6 5">
      <inertial pos="0 0 0" mass="0.1" diaginertia="1.66667e-06 1.66667e-06 1.66667e-06"/>
      <joint pos="0 0 0" axis="1 0 0" type="slide"/>
      <joint pos="0 0 0" axis="0 1 0" type="slide"/>
      <joint pos="0 0 0" axis="0 0 1" type="slide"/>
      <site name="site_6_6_5" pos="0 0 0" size="0.005"/>
    </body>
    <body name="vsr_24" pos="6 6 6">
      <inertial pos="0 0 0" mass="0.1" diaginertia="1.66667e-06 1.66667e-06 1.66667e-06"/>
      <joint pos="0 0 0" axis="1 0 0" type="slide"/>
      <joint pos="0 0 0" axis="0 1 0" type="slide"/>
      <joint pos="0 0 0" axis="0 0 1" type="slide"/>
      <site name="site_6_6_6" pos="0 0 0" size="0.005"/>
    </body>
    <body name="vsr_25" pos="7 4 4">
      <inertial pos="0 0 0" mass="0.1" diaginertia="1.66667e-06 1.66667e-06 1.66667e-06"/>
      <joint pos="0 0 0" axis="1 0 0" type="slide"/>
      <joint pos="0 0 0" axis="0 1 0" type="slide"/>
      <joint pos="0 0 0" axis="0 0 1" type="slide"/>
      <site name="site_7_4_4" pos="0 0 0" size="0.005"/>
    </body>
    <body name="vsr_26" pos="7 4 5">
      <inertial pos="0 0 0" mass="0.1" diaginertia="1.66667e-06 1.66667e-06 1.66667e-06"/>
      <joint pos="0 0 0" axis="1 0 0" type="slide"/>
      <joint pos="0 0 0" axis="0 1 0" type="slide"/>
      <joint pos="0 0 0" axis="0 0 1" type="slide"/>
      <site name="site_7_4_5" pos="0 0 0" size="0.005"/>
    </body>
    <body name="vsr_27" pos="7 4 6">
      <inertial pos="0 0 0" mass="0.1" diaginertia="1.66667e-06 1.66667e-06 1.66667e-06"/>
      <joint pos="0 0 0" axis="1 0 0" type="slide"/>
      <joint pos="0 0 0" axis="0 1 0" type="slide"/>
      <joint pos="0 0 0" axis="0 0 1" type="slide"/>
      <site name="site_7_4_6" pos="0 0 0" size="0.005"/>
    </body>
    <body name="vsr_28" pos="7 5 4">
      <inertial pos="0 0 0" mass="0.1" diaginertia="1.66667e-06 1.66667e-06 1.66667e-06"/>
      <joint pos="0 0 0" axis="1 0 0" type="slide"/>
      <joint pos="0 0 0" axis="0 1 0" type="slide"/>
      <joint pos="0 0 0" axis="0 0 1" type="slide"/>
      <site name="site_7_5_4" pos="0 0 0" size="0.005"/>
    </body>
    <body name="vsr_29" pos="7 5 5">
      <inertial pos="0 0 0" mass="0.1" diaginertia="1.66667e-06 1.66667e-06 1.66667e-06"/>
      <joint pos="0 0 0" axis="1 0 0" type="slide"/>
      <joint pos="0 0 0" axis="0 1 0" type="slide"/>
      <joint pos="0 0 0" axis="0 0 1" type="slide"/>
      <site name="site_7_5_5" pos="0 0 0" size="0.005"/>
    </body>
    <body name="vsr_30" pos="7 5 6">
      <inertial pos="0 0 0" mass="0.1" diaginertia="1.66667e-06 1.66667e-06 1.66667e-06"/>
      <joint pos="0 0 0" axis="1 0 0" type="slide"/>
      <joint pos="0 0 0" axis="0 1 0" type="slide"/>
      <joint pos="0 0 0" axis="0 0 1" type="slide"/>
      <site name="site_7_5_6" pos="0 0 0" size="0.005"/>
    </body>
    <body name="vsr_31" pos="7 6 4">
      <inertial pos="0 0 0" mass="0.1" diaginertia="1.66667e-06 1.66667e-06 1.66667e-06"/>
      <joint pos="0 0 0" axis="1 0 0" type="slide"/>
      <joint pos="0 0 0" axis="0 1 0" type="slide"/>
      <joint pos="0 0 0" axis="0 0 1" type="slide"/>
      <site name="site_7_6_4" pos="0 0 0" size="0.005"/>
    </body>
    <body name="vsr_32" pos="7 6 5">
      <inertial pos="0 0 0" mass="0.1" diaginertia="1.66667e-06 1.66667e-06 1.66667e-06"/>
      <joint pos="0 0 0" axis="1 0 0" type="slide"/>
      <joint pos="0 0 0" axis="0 1 0" type="slide"/>
      <joint pos="0 0 0" axis="0 0 1" type="slide"/>
      <site name="site_7_6_5" pos="0 0 0" size="0.005"/>
    </body>
    <body name="vsr_33" pos="7 6 6">
      <inertial pos="0 0 0" mass="0.1" diaginertia="1.66667e-06 1.66667e-06 1.66667e-06"/>
      <joint pos="0 0 0" axis="1 0 0" type="slide"/>
      <joint pos="0 0 0" axis="0 1 0" type="slide"/>
      <joint pos="0 0 0" axis="0 0 1" type="slide"/>
      <site name="site_7_6_6" pos="0 0 0" size="0.005"/>
    </body>
    <body name="vsr_34" pos="8 4 4">
      <inertial pos="0 0 0" mass="0.1" diaginertia="1.66667e-06 1.66667e-06 1.66667e-06"/>
      <joint pos="0 0 0" axis="1 0 0" type="slide"/>
      <joint pos="0 0 0" axis="0 1 0" type="slide"/>
      <joint pos="0 0 0" axis="0 0 1" type="slide"/>
      <site name="site_8_4_4" pos="0 0 0" size="0.005"/>
    </body>
    <body name="vsr_35" pos="8 4 5">
      <inertial pos="0 0 0" mass="0.1" diaginertia="1.66667e-06 1.66667e-06 1.66667e-06"/>
      <joint pos="0 0 0" axis="1 0 0" type="slide"/>
      <joint pos="0 0 0" axis="0 1 0" type="slide"/>
      <joint pos="0 0 0" axis="0 0 1" type="slide"/>
      <site name="site_8_4_5" pos="0 0 0" size="0.005"/>
    </body>
    <body name="vsr_36" pos="8 4 6">
      <inertial pos="0 0 0" mass="0.1" diaginertia="1.66667e-06 1.66667e-06 1.66667e-06"/>
      <joint pos="0 0 0" axis="1 0 0" type="slide"/>
      <joint pos="0 0 0" axis="0 1 0" type="slide"/>
      <joint pos="0 0 0" axis="0 0 1" type="slide"/>
      <site name="site_8_4_6" pos="0 0 0" size="0.005"/>
    </body>
    <body name="vsr_37" pos="8 5 4">
      <inertial pos="0 0 0" mass="0.1" diaginertia="1.66667e-06 1.66667e-06 1.66667e-06"/>
      <joint pos="0 0 0" axis="1 0 0" type="slide"/>
      <joint pos="0 0 0" axis="0 1 0" type="slide"/>
      <joint pos="0 0 0" axis="0 0 1" type="slide"/>
      <site name="site_8_5_4" pos="0 0 0" size="0.005"/>
    </body>
    <body name="vsr_38" pos="8 5 5">
      <inertial pos="0 0 0" mass="0.1" diaginertia="1.66667e-06 1.66667e-06 1.66667e-06"/>
      <joint pos="0 0 0" axis="1 0 0" type="slide"/>
      <joint pos="0 0 0" axis="0 1 0" type="slide"/>
      <joint pos="0 0 0" axis="0 0 1" type="slide"/>
      <site name="site_8_5_5" pos="0 0 0" size="0.005"/>
    </body>
    <body name="vsr_39" pos="8 5 6">
      <inertial pos="0 0 0" mass="0.1" diaginertia="1.66667e-06 1.66667e-06 1.66667e-06"/>
      <joint pos="0 0 0" axis="1 0 0" type="slide"/>
      <joint pos="0 0 0" axis="0 1 0" type="slide"/>
      <joint pos="0 0 0" axis="0 0 1" type="slide"/>
      <site name="site_8_5_6" pos="0 0 0" size="0.005"/>
    </body>
    <body name="vsr_40" pos="8 6 4">
      <inertial pos="0 0 0" mass="0.1" diaginertia="1.66667e-06 1.66667e-06 1.66667e-06"/>
      <joint pos="0 0 0" axis="1 0 0" type="slide"/>
      <joint pos="0 0 0" axis="0 1 0" type="slide"/>
      <joint pos="0 0 0" axis="0 0 1" type="slide"/>
      <site name="site_8_6_4" pos="0 0 0" size="0.005"/>
    </body>
    <body name="vsr_41" pos="8 6 5">
      <inertial pos="0 0 0" mass="0.1" diaginertia="1.66667e-06 1.66667e-06 1.66667e-06"/>
      <joint pos="0 0 0" axis="1 0 0" type="slide"/>
      <joint pos="0 0 0" axis="0 1 0" type="slide"/>
      <joint pos="0 0 0" axis="0 0 1" type="slide"/>
      <site name="site_8_6_5" pos="0 0 0" size="0.005"/>
    </body>
    <body name="vsr_42" pos="8 6 6">
      <inertial pos="0 0 0" mass="0.1" diaginertia="1.66667e-06 1.66667e-06 1.66667e-06"/>
      <joint pos="0 0 0" axis="1 0 0" type="slide"/>
      <joint pos="0 0 0" axis="0 1 0" type="slide"/>
      <joint pos="0 0 0" axis="0 0 1" type="slide"/>
      <site name="site_8_6_6" pos="0 0 0" size="0.005"/>
    </body>
  </worldbody>
  <deformable>
    <flex name="vsr" rgba="0.1 0.9 0.1 1" dim="3" body="vsr_0 vsr_1 vsr_2 vsr_3 vsr_4 vsr_5 vsr_6 vsr_7 vsr_8 vsr_9 vsr_10 vsr_11 vsr_12 vsr_13 vsr_14 vsr_15 vsr_16 vsr_17 vsr_18 vsr_19 vsr_20 vsr_21 vsr_22 vsr_23 vsr_24 vsr_25 vsr_26 vsr_27 vsr_28 vsr_29 vsr_30 vsr_31 vsr_32 vsr_33 vsr_34 vsr_35 vsr_36 vsr_37 vsr_38 vsr_39 vsr_40 vsr_41 vsr_42" element="0 3 2 11 0 1 3 11 0 8 1 11 0 7 8 11 0 10 7 11 0 2 10 11 3 6 5 15 3 4 6 15 3 12 4 15 3 11 12 15 3 14 11 15 3 5 14 15 7 11 10 20 7 8 11 20 7 17 8 20 7 16 17 20 7 19 16 20 7 10 19 20 8 12 11 21 8 9 12 21 8 18 9 21 8 17 18 21 8 20 17 21 8 11 20 21 10 14 13 23 10 11 14 23 10 20 11 23 10 19 20 23 10 22 19 23 10 13 22 23 11 15 14 24 11 12 15 24 11 21 12 24 11 20 21 24 11 23 20 24 11 14 23 24 16 20 19 29 16 17 20 29 16 26 17 29 16 25 26 29 16 28 25 29 16 19 28 29 17 21 20 30 17 18 21 30 17 27 18 30 17 26 27 30 17 29 26 30 17 20 29 30 19 23 22 32 19 20 23 32 19 29 20 32 19 28 29 32 19 31 28 32 19 22 31 32 20 24 23 33 20 21 24 33 20 30 21 33 20 29 30 33 20 32 29 33 20 23 32 33 25 29 28 38 25 26 29 38 25 35 26 38 25 34 35 38 25 37 34 38 25 28 37 38 26 30 29 39 26 27 30 39 26 36 27 39 26 35 36 39 26 38 35 39 26 29 38 39 28 32 31 41 28 29 32 41 28 38 29 41 28 37 38 41 28 40 37 41 28 31 40 41 29 33 32 42 29 30 33 42 29 39 30 42 29 38 39 42 29 41 38 42 29 32 41 42">
      <contact solref="0.01 1" solimp="0.95 0.99 0.0001 0.5 2" selfcollide="none"/>
      <elasticity young="250" poisson="0.3"/>
      <edge damping="1"/>
    </flex>
  </deformable>
  <tendon>
    <spatial name="voxel_4_4_4_spatial_4_4_4_to_5_5_5" width="0.006" rgba="1 0 0 1" stiffness="1" damping="0">
      <site site="site_4_4_4"/>
      <site site="site_5_5_5"/>
    </spatial>
    <spatial name="voxel_4_4_4_spatial_5_5_4_to_4_4_5" width="0.006" rgba="0 1 0 1" stiffness="1" damping="0">
      <site site="site_5_5_4"/>
      <site site="site_4_4_5"/>
    </spatial>
    <spatial name="voxel_4_4_4_spatial_4_5_4_to_5_4_5" width="0.006" rgba="0 0 1 1" stiffness="1" damping="0">
      <site site="site_4_5_4"/>
      <site site="site_5_4_5"/>
    </spatial>
    <spatial name="voxel_4_4_4_spatial_5_4_4_to_4_5_5" width="0.006" rgba="1 0 1 1" stiffness="1" damping="0">
      <site site="site_5_4_4"/>
      <site site="site_4_5_5"/>
    </spatial>
    <spatial name="voxel_4_5_5_spatial_4_5_5_to_5_6_6" width="0.006" rgba="1 0 0 1" stiffness="1" damping="0">
      <site site="site_4_5_5"/>
      <site site="site_5_6_6"/>
    </spatial>
    <spatial name="voxel_4_5_5_spatial_5_6_5_to_4_5_6" width="0.006" rgba="0 1 0 1" stiffness="1" damping="0">
      <site site="site_5_6_5"/>
      <site site="site_4_5_6"/>
    </spatial>
    <spatial name="voxel_4_5_5_spatial_4_6_5_to_5_5_6" width="0.006" rgba="0 0 1 1" stiffness="1" damping="0">
      <site site="site_4_6_5"/>
      <site site="site_5_5_6"/>
    </spatial>
    <spatial name="voxel_4_5_5_spatial_5_5_5_to_4_6_6" width="0.006" rgba="1 0 1 1" stiffness="1" damping="0">
      <site site="site_5_5_5"/>
      <site site="site_4_6_6"/>
    </spatial>
    <spatial name="voxel_5_4_4_spatial_5_4_4_to_6_5_5" width="0.006" rgba="1 0 0 1" stiffness="1" damping="0">
      <site site="site_5_4_4"/>
      <site site="site_6_5_5"/>
    </spatial>
    <spatial name="voxel_5_4_4_spatial_6_5_4_to_5_4_5" width="0.006" rgba="0 1 0 1" stiffness="1" damping="0">
      <site site="site_6_5_4"/>
      <site site="site_5_4_5"/>
    </spatial>
    <spatial name="voxel_5_4_4_spatial_5_5_4_to_6_4_5" width="0.006" rgba="0 0 1 1" stiffness="1" damping="0">
      <site site="site_5_5_4"/>
      <site site="site_6_4_5"/>
    </spatial>
    <spatial name="voxel_5_4_4_spatial_6_4_4_to_5_5_5" width="0.006" rgba="1 0 1 1" stiffness="1" damping="0">
      <site site="site_6_4_4"/>
      <site site="site_5_5_5"/>
    </spatial>
    <spatial name="voxel_5_4_5_spatial_5_4_5_to_6_5_6" width="0.006" rgba="1 0 0 1" stiffness="1" damping="0">
      <site site="site_5_4_5"/>
      <site site="site_6_5_6"/>
    </spatial>
    <spatial name="voxel_5_4_5_spatial_6_5_5_to_5_4_6" width="0.006" rgba="0 1 0 1" stiffness="1" damping="0">
      <site site="site_6_5_5"/>
      <site site="site_5_4_6"/>
    </spatial>
    <spatial name="voxel_5_4_5_spatial_5_5_5_to_6_4_6" width="0.006" rgba="0 0 1 1" stiffness="1" damping="0">
      <site site="site_5_5_5"/>
      <site site="site_6_4_6"/>
    </spatial>
    <spatial name="voxel_5_4_5_spatial_6_4_5_to_5_5_6" width="0.006" rgba="1 0 1 1" stiffness="1" damping="0">
      <site site="site_6_4_5"/>
      <site site="site_5_5_6"/>
    </spatial>
    <spatial name="voxel_5_5_4_spatial_5_5_4_to_6_6_5" width="0.006" rgba="1 0 0 1" stiffness="1" damping="0">
      <site site="site_5_5_4"/>
      <site site="site_6_6_5"/>
    </spatial>
    <spatial name="voxel_5_5_4_spatial_6_6_4_to_5_5_5" width="0.006" rgba="0 1 0 1" stiffness="1" damping="0">
      <site site="site_6_6_4"/>
      <site site="site_5_5_5"/>
    </spatial>
    <spatial name="voxel_5_5_4_spatial_5_6_4_to_6_5_5" width="0.006" rgba="0 0 1 1" stiffness="1" damping="0">
      <site site="site_5_6_4"/>
      <site site="site_6_5_5"/>
    </spatial>
    <spatial name="voxel_5_5_4_spatial_6_5_4_to_5_6_5" width="0.006" rgba="1 0 1 1" stiffness="1" damping="0">
      <site site="site_6_5_4"/>
      <site site="site_5_6_5"/>
    </spatial>
    <spatial name="voxel_5_5_5_spatial_5_5_5_to_6_6_6" width="0.006" rgba="1 0 0 1" stiffness="1" damping="0">
      <site site="site_5_5_5"/>
      <site site="site_6_6_6"/>
    </spatial>
    <spatial name="voxel_5_5_5_spatial_6_6_5_to_5_5_6" width="0.006" rgba="0 1 0 1" stiffness="1" damping="0">
      <site site="site_6_6_5"/>
      <site site="site_5_5_6"/>
    </spatial>
    <spatial name="voxel_5_5_5_spatial_5_6_5_to_6_5_6" width="0.006" rgba="0 0 1 1" stiffness="1" damping="0">
      <site site="site_5_6_5"/>
      <site site="site_6_5_6"/>
    </spatial>
    <spatial name="voxel_5_5_5_spatial_6_5_5_to_5_6_6" width="0.006" rgba="1 0 1 1" stiffness="1" damping="0">
      <site site="site_6_5_5"/>
      <site site="site_5_6_6"/>
    </spatial>
    <spatial name="voxel_6_4_4_spatial_6_4_4_to_7_5_5" width="0.006" rgba="1 0 0 1" stiffness="1" damping="0">
      <site site="site_6_4_4"/>
      <site site="site_7_5_5"/>
    </spatial>
    <spatial name="voxel_6_4_4_spatial_7_5_4_to_6_4_5" width="0.006" rgba="0 1 0 1" stiffness="1" damping="0">
      <site site="site_7_5_4"/>
      <site site="site_6_4_5"/>
    </spatial>
    <spatial name="voxel_6_4_4_spatial_6_5_4_to_7_4_5" width="0.006" rgba="0 0 1 1" stiffness="1" damping="0">
      <site site="site_6_5_4"/>
      <site site="site_7_4_5"/>
    </spatial>
    <spatial name="voxel_6_4_4_spatial_7_4_4_to_6_5_5" width="0.006" rgba="1 0 1 1" stiffness="1" damping="0">
      <site site="site_7_4_4"/>
      <site site="site_6_5_5"/>
    </spatial>
    <spatial name="voxel_6_4_5_spatial_6_4_5_to_7_5_6" width="0.006" rgba="1 0 0 1" stiffness="1" damping="0">
      <site site="site_6_4_5"/>
      <site site="site_7_5_6"/>
    </spatial>
    <spatial name="voxel_6_4_5_spatial_7_5_5_to_6_4_6" width="0.006" rgba="0 1 0 1" stiffness="1" damping="0">
      <site site="site_7_5_5"/>
      <site site="site_6_4_6"/>
    </spatial>
    <spatial name="voxel_6_4_5_spatial_6_5_5_to_7_4_6" width="0.006" rgba="0 0 1 1" stiffness="1" damping="0">
      <site site="site_6_5_5"/>
      <site site="site_7_4_6"/>
    </spatial>
    <spatial name="voxel_6_4_5_spatial_7_4_5_to_6_5_6" width="0.006" rgba="1 0 1 1" stiffness="1" damping="0">
      <site site="site_7_4_5"/>
      <site site="site_6_5_6"/>
    </spatial>
    <spatial name="voxel_6_5_4_spatial_6_5_4_to_7_6_5" width="0.006" rgba="1 0 0 1" stiffness="1" damping="0">
      <site site="site_6_5_4"/>
      <site site="site_7_6_5"/>
    </spatial>
    <spatial name="voxel_6_5_4_spatial_7_6_4_to_6_5_5" width="0.006" rgba="0 1 0 1" stiffness="1" damping="0">
      <site site="site_7_6_4"/>
      <site site="site_6_5_5"/>
    </spatial>
    <spatial name="voxel_6_5_4_spatial_6_6_4_to_7_5_5" width="0.006" rgba="0 0 1 1" stiffness="1" damping="0">
      <site site="site_6_6_4"/>
      <site site="site_7_5_5"/>
    </spatial>
    <spatial name="voxel_6_5_4_spatial_7_5_4_to_6_6_5" width="0.006" rgba="1 0 1 1" stiffness="1" damping="0">
      <site site="site_7_5_4"/>
      <site site="site_6_6_5"/>
    </spatial>
    <spatial name="voxel_6_5_5_spatial_6_5_5_to_7_6_6" width="0.006" rgba="1 0 0 1" stiffness="1" damping="0">
      <site site="site_6_5_5"/>
      <site site="site_7_6_6"/>
    </spatial>
    <spatial name="voxel_6_5_5_spatial_7_6_5_to_6_5_6" width="0.006" rgba="0 1 0 1" stiffness="1" damping="0">
      <site site="site_7_6_5"/>
      <site site="site_6_5_6"/>
    </spatial>
    <spatial name="voxel_6_5_5_spatial_6_6_5_to_7_5_6" width="0.006" rgba="0 0 1 1" stiffness="1" damping="0">
      <site site="site_6_6_5"/>
      <site site="site_7_5_6"/>
    </spatial>
    <spatial name="voxel_6_5_5_spatial_7_5_5_to_6_6_6" width="0.006" rgba="1 0 1 1" stiffness="1" damping="0">
      <site site="site_7_5_5"/>
      <site site="site_6_6_6"/>
    </spatial>
    <spatial name="voxel_7_4_4_spatial_7_4_4_to_8_5_5" width="0.006" rgba="1 0 0 1" stiffness="1" damping="0">
      <site site="site_7_4_4"/>
      <site site="site_8_5_5"/>
    </spatial>
    <spatial name="voxel_7_4_4_spatial_8_5_4_to_7_4_5" width="0.006" rgba="0 1 0 1" stiffness="1" damping="0">
      <site site="site_8_5_4"/>
      <site site="site_7_4_5"/>
    </spatial>
    <spatial name="voxel_7_4_4_spatial_7_5_4_to_8_4_5" width="0.006" rgba="0 0 1 1" stiffness="1" damping="0">
      <site site="site_7_5_4"/>
      <site site="site_8_4_5"/>
    </spatial>
    <spatial name="voxel_7_4_4_spatial_8_4_4_to_7_5_5" width="0.006" rgba="1 0 1 1" stiffness="1" damping="0">
      <site site="site_8_4_4"/>
      <site site="site_7_5_5"/>
    </spatial>
    <spatial name="voxel_7_4_5_spatial_7_4_5_to_8_5_6" width="0.006" rgba="1 0 0 1" stiffness="1" damping="0">
      <site site="site_7_4_5"/>
      <site site="site_8_5_6"/>
    </spatial>
    <spatial name="voxel_7_4_5_spatial_8_5_5_to_7_4_6" width="0.006" rgba="0 1 0 1" stiffness="1" damping="0">
      <site site="site_8_5_5"/>
      <site site="site_7_4_6"/>
    </spatial>
    <spatial name="voxel_7_4_5_spatial_7_5_5_to_8_4_6" width="0.006" rgba="0 0 1 1" stiffness="1" damping="0">
      <site site="site_7_5_5"/>
      <site site="site_8_4_6"/>
    </spatial>
    <spatial name="voxel_7_4_5_spatial_8_4_5_to_7_5_6" width="0.006" rgba="1 0 1 1" stiffness="1" damping="0">
      <site site="site_8_4_5"/>
      <site site="site_7_5_6"/>
    </spatial>
    <spatial name="voxel_7_5_4_spatial_7_5_4_to_8_6_5" width="0.006" rgba="1 0 0 1" stiffness="1" damping="0">
      <site site="site_7_5_4"/>
      <site site="site_8_6_5"/>
    </spatial>
    <spatial name="voxel_7_5_4_spatial_8_6_4_to_7_5_5" width="0.006" rgba="0 1 0 1" stiffness="1" damping="0">
      <site site="site_8_6_4"/>
      <site site="site_7_5_5"/>
    </spatial>
    <spatial name="voxel_7_5_4_spatial_7_6_4_to_8_5_5" width="0.006" rgba="0 0 1 1" stiffness="1" damping="0">
      <site site="site_7_6_4"/>
      <site site="site_8_5_5"/>
    </spatial>
    <spatial name="voxel_7_5_4_spatial_8_5_4_to_7_6_5" width="0.006" rgba="1 0 1 1" stiffness="1" damping="0">
      <site site="site_8_5_4"/>
      <site site="site_7_6_5"/>
    </spatial>
    <spatial name="voxel_7_5_5_spatial_7_5_5_to_8_6_6" width="0.006" rgba="1 0 0 1" stiffness="1" damping="0">
      <site site="site_7_5_5"/>
      <site site="site_8_6_6"/>
    </spatial>
    <spatial name="voxel_7_5_5_spatial_8_6_5_to_7_5_6" width="0.006" rgba="0 1 0 1" stiffness="1" damping="0">
      <site site="site_8_6_5"/>
      <site site="site_7_5_6"/>
    </spatial>
    <spatial name="voxel_7_5_5_spatial_7_6_5_to_8_5_6" width="0.006" rgba="0 0 1 1" stiffness="1" damping="0">
      <site site="site_7_6_5"/>
      <site site="site_8_5_6"/>
    </spatial>
    <spatial name="voxel_7_5_5_spatial_8_5_5_to_7_6_6" width="0.006" rgba="1 0 1 1" stiffness="1" damping="0">
      <site site="site_8_5_5"/>
      <site site="site_7_6_6"/>
    </spatial>
  </tendon>
  <actuator>
    <motor name="voxel_4_4_4_motor_4_4_4_to_5_5_5" tendon="voxel_4_4_4_spatial_4_4_4_to_5_5_5" ctrlrange="0 1" gear="100.0"/>
    <motor name="voxel_4_4_4_motor_5_5_4_to_4_4_5" tendon="voxel_4_4_4_spatial_5_5_4_to_4_4_5" ctrlrange="0 1" gear="100.0"/>
    <motor name="voxel_4_4_4_motor_4_5_4_to_5_4_5" tendon="voxel_4_4_4_spatial_4_5_4_to_5_4_5" ctrlrange="0 1" gear="100.0"/>
    <motor name="voxel_4_4_4_motor_5_4_4_to_4_5_5" tendon="voxel_4_4_4_spatial_5_4_4_to_4_5_5" ctrlrange="0 1" gear="100.0"/>
    <motor name="voxel_4_5_5_motor_4_5_5_to_5_6_6" tendon="voxel_4_5_5_spatial_4_5_5_to_5_6_6" ctrlrange="0 1" gear="100.0"/>
    <motor name="voxel_4_5_5_motor_5_6_5_to_4_5_6" tendon="voxel_4_5_5_spatial_5_6_5_to_4_5_6" ctrlrange="0 1" gear="100.0"/>
    <motor name="voxel_4_5_5_motor_4_6_5_to_5_5_6" tendon="voxel_4_5_5_spatial_4_6_5_to_5_5_6" ctrlrange="0 1" gear="100.0"/>
    <motor name="voxel_4_5_5_motor_5_5_5_to_4_6_6" tendon="voxel_4_5_5_spatial_5_5_5_to_4_6_6" ctrlrange="0 1" gear="100.0"/>
    <motor name="voxel_5_4_4_motor_5_4_4_to_6_5_5" tendon="voxel_5_4_4_spatial_5_4_4_to_6_5_5" ctrlrange="0 1" gear="100.0"/>
    <motor name="voxel_5_4_4_motor_6_5_4_to_5_4_5" tendon="voxel_5_4_4_spatial_6_5_4_to_5_4_5" ctrlrange="0 1" gear="100.0"/>
    <motor name="voxel_5_4_4_motor_5_5_4_to_6_4_5" tendon="voxel_5_4_4_spatial_5_5_4_to_6_4_5" ctrlrange="0 1" gear="100.0"/>
    <motor name="voxel_5_4_4_motor_6_4_4_to_5_5_5" tendon="voxel_5_4_4_spatial_6_4_4_to_5_5_5" ctrlrange="0 1" gear="100.0"/>
    <motor name="voxel_5_4_5_motor_5_4_5_to_6_5_6" tendon="voxel_5_4_5_spatial_5_4_5_to_6_5_6" ctrlrange="0 1" gear="100.0"/>
    <motor name="voxel_5_4_5_motor_6_5_5_to_5_4_6" tendon="voxel_5_4_5_spatial_6_5_5_to_5_4_6" ctrlrange="0 1" gear="100.0"/>
    <motor name="voxel_5_4_5_motor_5_5_5_to_6_4_6" tendon="voxel_5_4_5_spatial_5_5_5_to_6_4_6" ctrlrange="0 1" gear="100.0"/>
    <motor name="voxel_5_4_5_motor_6_4_5_to_5_5_6" tendon="voxel_5_4_5_spatial_6_4_5_to_5_5_6" ctrlrange="0 1" gear="100.0"/>
    <motor name="voxel_5_5_4_motor_5_5_4_to_6_6_5" tendon="voxel_5_5_4_spatial_5_5_4_to_6_6_5" ctrlrange="0 1" gear="100.0"/>
    <motor name="voxel_5_5_4_motor_6_6_4_to_5_5_5" tendon="voxel_5_5_4_spatial_6_6_4_to_5_5_5" ctrlrange="0 1" gear="100.0"/>
    <motor name="voxel_5_5_4_motor_5_6_4_to_6_5_5" tendon="voxel_5_5_4_spatial_5_6_4_to_6_5_5" ctrlrange="0 1" gear="100.0"/>
    <motor name="voxel_5_5_4_motor_6_5_4_to_5_6_5" tendon="voxel_5_5_4_spatial_6_5_4_to_5_6_5" ctrlrange="0 1" gear="100.0"/>
    <motor name="voxel_5_5_5_motor_5_5_5_to_6_6_6" tendon="voxel_5_5_5_spatial_5_5_5_to_6_6_6" ctrlrange="0 1" gear="100.0"/>
    <motor name="voxel_5_5_5_motor_6_6_5_to_5_5_6" tendon="voxel_5_5_5_spatial_6_6_5_to_5_5_6" ctrlrange="0 1" gear="100.0"/>
    <motor name="voxel_5_5_5_motor_5_6_5_to_6_5_6" tendon="voxel_5_5_5_spatial_5_6_5_to_6_5_6" ctrlrange="0 1" gear="100.0"/>
    <motor name="voxel_5_5_5_motor_6_5_5_to_5_6_6" tendon="voxel_5_5_5_spatial_6_5_5_to_5_6_6" ctrlrange="0 1" gear="100.0"/>
    <motor name="voxel_6_4_4_motor_6_4_4_to_7_5_5" tendon="voxel_6_4_4_spatial_6_4_4_to_7_5_5" ctrlrange="0 1" gear="100.0"/>
    <motor name="voxel_6_4_4_motor_7_5_4_to_6_4_5" tendon="voxel_6_4_4_spatial_7_5_4_to_6_4_5" ctrlrange="0 1" gear="100.0"/>
    <motor name="voxel_6_4_4_motor_6_5_4_to_7_4_5" tendon="voxel_6_4_4_spatial_6_5_4_to_7_4_5" ctrlrange="0 1" gear="100.0"/>
    <motor name="voxel_6_4_4_motor_7_4_4_to_6_5_5" tendon="voxel_6_4_4_spatial_7_4_4_to_6_5_5" ctrlrange="0 1" gear="100.0"/>
    <motor name="voxel_6_4_5_motor_6_4_5_to_7_5_6" tendon="voxel_6_4_5_spatial_6_4_5_to_7_5_6" ctrlrange="0 1" gear="100.0"/>
    <motor name="voxel_6_4_5_motor_7_5_5_to_6_4_6" tendon="voxel_6_4_5_spatial_7_5_5_to_6_4_6" ctrlrange="0 1" gear="100.0"/>
    <motor name="voxel_6_4_5_motor_6_5_5_to_7_4_6" tendon="voxel_6_4_5_spatial_6_5_5_to_7_4_6" ctrlrange="0 1" gear="100.0"/>
    <motor name="voxel_6_4_5_motor_7_4_5_to_6_5_6" tendon="voxel_6_4_5_spatial_7_4_5_to_6_5_6" ctrlrange="0 1" gear="100.0"/>
    <motor name="voxel_6_5_4_motor_6_5_4_to_7_6_5" tendon="voxel_6_5_4_spatial_6_5_4_to_7_6_5" ctrlrange="0 1" gear="100.0"/>
    <motor name="voxel_6_5_4_motor_7_6_4_to_6_5_5" tendon="voxel_6_5_4_spatial_7_6_4_to_6_5_5" ctrlrange="0 1" gear="100.0"/>
    <motor name="voxel_6_5_4_motor_6_6_4_to_7_5_5" tendon="voxel_6_5_4_spatial_6_6_4_to_7_5_5" ctrlrange="0 1" gear="100.0"/>
    <motor name="voxel_6_5_4_motor_7_5_4_to_6_6_5" tendon="voxel_6_5_4_spatial_7_5_4_to_6_6_5" ctrlrange="0 1" gear="100.0"/>
    <motor name="voxel_6_5_5_motor_6_5_5_to_7_6_6" tendon="voxel_6_5_5_spatial_6_5_5_to_7_6_6" ctrlrange="0 1" gear="100.0"/>
    <motor name="voxel_6_5_5_motor_7_6_5_to_6_5_6" tendon="voxel_6_5_5_spatial_7_6_5_to_6_5_6" ctrlrange="0 1" gear="100.0"/>
    <motor name="voxel_6_5_5_motor_6_6_5_to_7_5_6" tendon="voxel_6_5_5_spatial_6_6_5_to_7_5_6" ctrlrange="0 1" gear="100.0"/>
    <motor name="voxel_6_5_5_motor_7_5_5_to_6_6_6" tendon="voxel_6_5_5_spatial_7_5_5_to_6_6_6" ctrlrange="0 1" gear="100.0"/>
    <motor name="voxel_7_4_4_motor_7_4_4_to_8_5_5" tendon="voxel_7_4_4_spatial_7_4_4_to_8_5_5" ctrlrange="0 1" gear="100.0"/>
    <motor name="voxel_7_4_4_motor_8_5_4_to_7_4_5" tendon="voxel_7_4_4_spatial_8_5_4_to_7_4_5" ctrlrange="0 1" gear="100.0"/>
    <motor name="voxel_7_4_4_motor_7_5_4_to_8_4_5" tendon="voxel_7_4_4_spatial_7_5_4_to_8_4_5" ctrlrange="0 1" gear="100.0"/>
    <motor name="voxel_7_4_4_motor_8_4_4_to_7_5_5" tendon="voxel_7_4_4_spatial_8_4_4_to_7_5_5" ctrlrange="0 1" gear="100.0"/>
    <motor name="voxel_7_4_5_motor_7_4_5_to_8_5_6" tendon="voxel_7_4_5_spatial_7_4_5_to_8_5_6" ctrlrange="0 1" gear="100.0"/>
    <motor name="voxel_7_4_5_motor_8_5_5_to_7_4_6" tendon="voxel_7_4_5_spatial_8_5_5_to_7_4_6" ctrlrange="0 1" gear="100.0"/>
    <motor name="voxel_7_4_5_motor_7_5_5_to_8_4_6" tendon="voxel_7_4_5_spatial_7_5_5_to_8_4_6" ctrlrange="0 1" gear="100.0"/>
    <motor name="voxel_7_4_5_motor_8_4_5_to_7_5_6" tendon="voxel_7_4_5_spatial_8_4_5_to_7_5_6" ctrlrange="0 1" gear="100.0"/>
    <motor name="voxel_7_5_4_motor_7_5_4_to_8_6_5" tendon="voxel_7_5_4_spatial_7_5_4_to_8_6_5" ctrlrange="0 1" gear="100.0"/>
    <motor name="voxel_7_5_4_motor_8_6_4_to_7_5_5" tendon="voxel_7_5_4_spatial_8_6_4_to_7_5_5" ctrlrange="0 1" gear="100.0"/>
    <motor name="voxel_7_5_4_motor_7_6_4_to_8_5_5" tendon="voxel_7_5_4_spatial_7_6_4_to_8_5_5" ctrlrange="0 1" gear="100.0"/>
    <motor name="voxel_7_5_4_motor_8_5_4_to_7_6_5" tendon="voxel_7_5_4_spatial_8_5_4_to_7_6_5" ctrlrange="0 1" gear="100.0"/>
    <motor name="voxel_7_5_5_motor_7_5_5_to_8_6_6" tendon="voxel_7_5_5_spatial_7_5_5_to_8_6_6" ctrlrange="0 1" gear="100.0"/>
    <motor name="voxel_7_5_5_motor_8_6_5_to_7_5_6" tendon="voxel_7_5_5_spatial_8_6_5_to_7_5_6" ctrlrange="0 1" gear="100.0"/>
    <motor name="voxel_7_5_5_motor_7_6_5_to_8_5_6" tendon="voxel_7_5_5_spatial_7_6_5_to_8_5_6" ctrlrange="0 1" gear="100.0"/>
    <motor name="voxel_7_5_5_motor_8_5_5_to_7_6_6" tendon="voxel_7_5_5_spatial_8_5_5_to_7_6_6" ctrlrange="0 1" gear="100.0"/>
  </actuator>
</mujoco>