<?xml version="1.0" ?>
<mujoco model="MuJoCo Model">
  <compiler angle="radian" meshdir="asset/" texturedir="asset/"/>
  <option timestep="0.001" tolerance="1e-06" integrator="implicitfast"/>
  <size memory="2000M"/>
  <visual>
    <map stiffness="700" fogstart="1" fogend="15" zfar="40" haze="1" shadowscale="0.5"/>
    <rgba haze="0.15 0.25 0.35 1"/>
  </visual>
  <statistic meansize="0.05"/>
  <asset>
    <texture type="skybox" builtin="gradient" rgb1="0.3 0.5 0.7" rgb2="0 0 0" width="512" height="3072"/>
    <texture type="2d" name="texplane" builtin="checker" mark="cross" rgb1="0.2 0.3 0.4" rgb2="0.1 0.15 0.2" markrgb="0.8 0.8 0.8" width="512" height="512"/>
    <material name="matplane" texture="texplane" texuniform="true" texrepeat="10 10" reflectance="0.3"/>
  </asset>
  <worldbody>
    <geom name="ground" size="0 0 1" pos="0 0 -2" type="plane" condim="1" material="matplane"/>
    <light pos="30 30 20" dir="0 0 -1" diffuse="0.4 0.4 0.4" specular="0.1 0.1 0.1"/>
    <light pos="-20 -20 40" dir="0.0990148 0.0990148 -0.990148" directional="true" diffuse="0.8 0.8 0.8" specular="0.2 0.2 0.2"/>
    <body name="target" pos="-300 3 3.5">
      <geom size="1 1 3" type="box" rgba="1 0 0 0.7"/>
      <site name="site_-300_3_3.5" pos="0 0 0" size="0.005"/>
    </body>
    <body name="vsr_0" pos="0 0 0">
      <inertial pos="0 0 0" mass="0.1" diaginertia="1.66667e-06 1.66667e-06 1.66667e-06"/>
      <joint pos="0 0 0" axis="1 0 0" type="slide"/>
      <joint pos="0 0 0" axis="0 1 0" type="slide"/>
      <joint pos="0 0 0" axis="0 0 1" type="slide"/>
      <site name="site_0_0_0" pos="0 0 0" size="0.005"/>
    </body>
    <body name="vsr_1" pos="0 0 1">
      <inertial pos="0 0 0" mass="0.1" diaginertia="1.66667e-06 1.66667e-06 1.66667e-06"/>
      <joint pos="0 0 0" axis="1 0 0" type="slide"/>
      <joint pos="0 0 0" axis="0 1 0" type="slide"/>
      <joint pos="0 0 0" axis="0 0 1" type="slide"/>
      <site name="site_0_0_1" pos="0 0 0" size="0.005"/>
    </body>
    <body name="vsr_2" pos="0 1 0">
      <inertial pos="0 0 0" mass="0.1" diaginertia="1.66667e-06 1.66667e-06 1.66667e-06"/>
      <joint pos="0 0 0" axis="1 0 0" type="slide"/>
      <joint pos="0 0 0" axis="0 1 0" type="slide"/>
      <joint pos="0 0 0" axis="0 0 1" type="slide"/>
      <site name="site_0_1_0" pos="0 0 0" size="0.005"/>
    </body>
    <body name="vsr_3" pos="0 1 1">
      <inertial pos="0 0 0" mass="0.1" diaginertia="1.66667e-06 1.66667e-06 1.66667e-06"/>
      <joint pos="0 0 0" axis="1 0 0" type="slide"/>
      <joint pos="0 0 0" axis="0 1 0" type="slide"/>
      <joint pos="0 0 0" axis="0 0 1" type="slide"/>
      <site name="site_0_1_1" pos="0 0 0" size="0.005"/>
    </body>
    <body name="vsr_4" pos="0 2 0">
      <inertial pos="0 0 0" mass="0.1" diaginertia="1.66667e-06 1.66667e-06 1.66667e-06"/>
      <joint pos="0 0 0" axis="1 0 0" type="slide"/>
      <joint pos="0 0 0" axis="0 1 0" type="slide"/>
      <joint pos="0 0 0" axis="0 0 1" type="slide"/>
      <site name="site_0_2_0" pos="0 0 0" size="0.005"/>
    </body>
    <body name="vsr_5" pos="0 2 1">
      <inertial pos="0 0 0" mass="0.1" diaginertia="1.66667e-06 1.66667e-06 1.66667e-06"/>
      <joint pos="0 0 0" axis="1 0 0" type="slide"/>
      <joint pos="0 0 0" axis="0 1 0" type="slide"/>
      <joint pos="0 0 0" axis="0 0 1" type="slide"/>
      <site name="site_0_2_1" pos="0 0 0" size="0.005"/>
    </body>
    <body name="vsr_6" pos="1 0 0">
      <inertial pos="0 0 0" mass="0.1" diaginertia="1.66667e-06 1.66667e-06 1.66667e-06"/>
      <joint pos="0 0 0" axis="1 0 0" type="slide"/>
      <joint pos="0 0 0" axis="0 1 0" type="slide"/>
      <joint pos="0 0 0" axis="0 0 1" type="slide"/>
      <site name="site_1_0_0" pos="0 0 0" size="0.005"/>
    </body>
    <body name="vsr_7" pos="1 0 1">
      <inertial pos="0 0 0" mass="0.1" diaginertia="1.66667e-06 1.66667e-06 1.66667e-06"/>
      <joint pos="0 0 0" axis="1 0 0" type="slide"/>
      <joint pos="0 0 0" axis="0 1 0" type="slide"/>
      <joint pos="0 0 0" axis="0 0 1" type="slide"/>
      <site name="site_1_0_1" pos="0 0 0" size="0.005"/>
    </body>
    <body name="vsr_8" pos="1 0 2">
      <inertial pos="0 0 0" mass="0.1" diaginertia="1.66667e-06 1.66667e-06 1.66667e-06"/>
      <joint pos="0 0 0" axis="1 0 0" type="slide"/>
      <joint pos="0 0 0" axis="0 1 0" type="slide"/>
      <joint pos="0 0 0" axis="0 0 1" type="slide"/>
      <site name="site_1_0_2" pos="0 0 0" size="0.005"/>
    </body>
    <body name="vsr_9" pos="1 1 0">
      <inertial pos="0 0 0" mass="0.1" diaginertia="1.66667e-06 1.66667e-06 1.66667e-06"/>
      <joint pos="0 0 0" axis="1 0 0" type="slide"/>
      <joint pos="0 0 0" axis="0 1 0" type="slide"/>
      <joint pos="0 0 0" axis="0 0 1" type="slide"/>
      <site name="site_1_1_0" pos="0 0 0" size="0.005"/>
    </body>
    <body name="vsr_10" pos="1 1 1">
      <inertial pos="0 0 0" mass="0.1" diaginertia="1.66667e-06 1.66667e-06 1.66667e-06"/>
      <joint pos="0 0 0" axis="1 0 0" type="slide"/>
      <joint pos="0 0 0" axis="0 1 0" type="slide"/>
      <joint pos="0 0 0" axis="0 0 1" type="slide"/>
      <site name="site_1_1_1" pos="0 0 0" size="0.005"/>
    </body>
    <body name="vsr_11" pos="1 1 2">
      <inertial pos="0 0 0" mass="0.1" diaginertia="1.66667e-06 1.66667e-06 1.66667e-06"/>
      <joint pos="0 0 0" axis="1 0 0" type="slide"/>
      <joint pos="0 0 0" axis="0 1 0" type="slide"/>
      <joint pos="0 0 0" axis="0 0 1" type="slide"/>
      <site name="site_1_1_2" pos="0 0 0" size="0.005"/>
    </body>
    <body name="vsr_12" pos="1 2 0">
      <inertial pos="0 0 0" mass="0.1" diaginertia="1.66667e-06 1.66667e-06 1.66667e-06"/>
      <joint pos="0 0 0" axis="1 0 0" type="slide"/>
      <joint pos="0 0 0" axis="0 1 0" type="slide"/>
      <joint pos="0 0 0" axis="0 0 1" type="slide"/>
      <site name="site_1_2_0" pos="0 0 0" size="0.005"/>
    </body>
    <body name="vsr_13" pos="1 2 1">
      <inertial pos="0 0 0" mass="0.1" diaginertia="1.66667e-06 1.66667e-06 1.66667e-06"/>
      <joint pos="0 0 0" axis="1 0 0" type="slide"/>
      <joint pos="0 0 0" axis="0 1 0" type="slide"/>
      <joint pos="0 0 0" axis="0 0 1" type="slide"/>
      <site name="site_1_2_1" pos="0 0 0" size="0.005"/>
    </body>
    <body name="vsr_14" pos="1 2 2">
      <inertial pos="0 0 0" mass="0.1" diaginertia="1.66667e-06 1.66667e-06 1.66667e-06"/>
      <joint pos="0 0 0" axis="1 0 0" type="slide"/>
      <joint pos="0 0 0" axis="0 1 0" type="slide"/>
      <joint pos="0 0 0" axis="0 0 1" type="slide"/>
      <site name="site_1_2_2" pos="0 0 0" size="0.005"/>
    </body>
    <body name="vsr_15" pos="2 0 0">
      <inertial pos="0 0 0" mass="0.1" diaginertia="1.66667e-06 1.66667e-06 1.66667e-06"/>
      <joint pos="0 0 0" axis="1 0 0" type="slide"/>
      <joint pos="0 0 0" axis="0 1 0" type="slide"/>
      <joint pos="0 0 0" axis="0 0 1" type="slide"/>
      <site name="site_2_0_0" pos="0 0 0" size="0.005"/>
    </body>
    <body name="vsr_16" pos="2 0 1">
      <inertial pos="0 0 0" mass="0.1" diaginertia="1.66667e-06 1.66667e-06 1.66667e-06"/>
      <joint pos="0 0 0" axis="1 0 0" type="slide"/>
      <joint pos="0 0 0" axis="0 1 0" type="slide"/>
      <joint pos="0 0 0" axis="0 0 1" type="slide"/>
      <site name="site_2_0_1" pos="0 0 0" size="0.005"/>
    </body>
    <body name="vsr_17" pos="2 0 2">
      <inertial pos="0 0 0" mass="0.1" diaginertia="1.66667e-06 1.66667e-06 1.66667e-06"/>
      <joint pos="0 0 0" axis="1 0 0" type="slide"/>
      <joint pos="0 0 0" axis="0 1 0" type="slide"/>
      <joint pos="0 0 0" axis="0 0 1" type="slide"/>
      <site name="site_2_0_2" pos="0 0 0" size="0.005"/>
    </body>
    <body name="vsr_18" pos="2 1 0">
      <inertial pos="0 0 0" mass="0.1" diaginertia="1.66667e-06 1.66667e-06 1.66667e-06"/>
      <joint pos="0 0 0" axis="1 0 0" type="slide"/>
      <joint pos="0 0 0" axis="0 1 0" type="slide"/>
      <joint pos="0 0 0" axis="0 0 1" type="slide"/>
      <site name="site_2_1_0" pos="0 0 0" size="0.005"/>
    </body>
    <body name="vsr_19" pos="2 1 1">
      <inertial pos="0 0 0" mass="0.1" diaginertia="1.66667e-06 1.66667e-06 1.66667e-06"/>
      <joint pos="0 0 0" axis="1 0 0" type="slide"/>
      <joint pos="0 0 0" axis="0 1 0" type="slide"/>
      <joint pos="0 0 0" axis="0 0 1" type="slide"/>
      <site name="site_2_1_1" pos="0 0 0" size="0.005"/>
    </body>
    <body name="vsr_20" pos="2 1 2">
      <inertial pos="0 0 0" mass="0.1" diaginertia="1.66667e-06 1.66667e-06 1.66667e-06"/>
      <joint pos="0 0 0" axis="1 0 0" type="slide"/>
      <joint pos="0 0 0" axis="0 1 0" type="slide"/>
      <joint pos="0 0 0" axis="0 0 1" type="slide"/>
      <site name="site_2_1_2" pos="0 0 0" size="0.005"/>
    </body>
    <body name="vsr_21" pos="2 2 0">
      <inertial pos="0 0 0" mass="0.1" diaginertia="1.66667e-06 1.66667e-06 1.66667e-06"/>
      <joint pos="0 0 0" axis="1 0 0" type="slide"/>
      <joint pos="0 0 0" axis="0 1 0" type="slide"/>
      <joint pos="0 0 0" axis="0 0 1" type="slide"/>
      <site name="site_2_2_0" pos="0 0 0" size="0.005"/>
    </body>
    <body name="vsr_22" pos="2 2 1">
      <inertial pos="0 0 0" mass="0.1" diaginertia="1.66667e-06 1.66667e-06 1.66667e-06"/>
      <joint pos="0 0 0" axis="1 0 0" type="slide"/>
      <joint pos="0 0 0" axis="0 1 0" type="slide"/>
      <joint pos="0 0 0" axis="0 0 1" type="slide"/>
      <site name="site_2_2_1" pos="0 0 0" size="0.005"/>
    </body>
    <body name="vsr_23" pos="2 2 2">
      <inertial pos="0 0 0" mass="0.1" diaginertia="1.66667e-06 1.66667e-06 1.66667e-06"/>
      <joint pos="0 0 0" axis="1 0 0" type="slide"/>
      <joint pos="0 0 0" axis="0 1 0" type="slide"/>
      <joint pos="0 0 0" axis="0 0 1" type="slide"/>
      <site name="site_2_2_2" pos="0 0 0" size="0.005"/>
    </body>
    <body name="vsr_24" pos="3 0 0">
      <inertial pos="0 0 0" mass="0.1" diaginertia="1.66667e-06 1.66667e-06 1.66667e-06"/>
      <joint pos="0 0 0" axis="1 0 0" type="slide"/>
      <joint pos="0 0 0" axis="0 1 0" type="slide"/>
      <joint pos="0 0 0" axis="0 0 1" type="slide"/>
      <site name="site_3_0_0" pos="0 0 0" size="0.005"/>
    </body>
    <body name="vsr_25" pos="3 0 1">
      <inertial pos="0 0 0" mass="0.1" diaginertia="1.66667e-06 1.66667e-06 1.66667e-06"/>
      <joint pos="0 0 0" axis="1 0 0" type="slide"/>
      <joint pos="0 0 0" axis="0 1 0" type="slide"/>
      <joint pos="0 0 0" axis="0 0 1" type="slide"/>
      <site name="site_3_0_1" pos="0 0 0" size="0.005"/>
    </body>
    <body name="vsr_26" pos="3 1 0">
      <inertial pos="0 0 0" mass="0.1" diaginertia="1.66667e-06 1.66667e-06 1.66667e-06"/>
      <joint pos="0 0 0" axis="1 0 0" type="slide"/>
      <joint pos="0 0 0" axis="0 1 0" type="slide"/>
      <joint pos="0 0 0" axis="0 0 1" type="slide"/>
      <site name="site_3_1_0" pos="0 0 0" size="0.005"/>
    </body>
    <body name="vsr_27" pos="3 1 1">
      <inertial pos="0 0 0" mass="0.1" diaginertia="1.66667e-06 1.66667e-06 1.66667e-06"/>
      <joint pos="0 0 0" axis="1 0 0" type="slide"/>
      <joint pos="0 0 0" axis="0 1 0" type="slide"/>
      <joint pos="0 0 0" axis="0 0 1" type="slide"/>
      <site name="site_3_1_1" pos="0 0 0" size="0.005"/>
    </body>
    <body name="vsr_28" pos="3 2 0">
      <inertial pos="0 0 0" mass="0.1" diaginertia="1.66667e-06 1.66667e-06 1.66667e-06"/>
      <joint pos="0 0 0" axis="1 0 0" type="slide"/>
      <joint pos="0 0 0" axis="0 1 0" type="slide"/>
      <joint pos="0 0 0" axis="0 0 1" type="slide"/>
      <site name="site_3_2_0" pos="0 0 0" size="0.005"/>
    </body>
    <body name="vsr_29" pos="3 2 1">
      <inertial pos="0 0 0" mass="0.1" diaginertia="1.66667e-06 1.66667e-06 1.66667e-06"/>
      <joint pos="0 0 0" axis="1 0 0" type="slide"/>
      <joint pos="0 0 0" axis="0 1 0" type="slide"/>
      <joint pos="0 0 0" axis="0 0 1" type="slide"/>
      <site name="site_3_2_1" pos="0 0 0" size="0.005"/>
    </body>
  </worldbody>
  <deformable>
    <flex name="vsr" rgba="0.1 0.9 0.1 1" dim="3" body="vsr_0 vsr_1 vsr_2 vsr_3 vsr_4 vsr_5 vsr_6 vsr_7 vsr_8 vsr_9 vsr_10 vsr_11 vsr_12 vsr_13 vsr_14 vsr_15 vsr_16 vsr_17 vsr_18 vsr_19 vsr_20 vsr_21 vsr_22 vsr_23 vsr_24 vsr_25 vsr_26 vsr_27 vsr_28 vsr_29" element="0 3 2 10 0 1 3 10 0 7 1 10 0 6 7 10 0 9 6 10 0 2 9 10 2 5 4 13 2 3 5 13 2 10 3 13 2 9 10 13 2 12 9 13 2 4 12 13 6 10 9 19 6 7 10 19 6 16 7 19 6 15 16 19 6 18 15 19 6 9 18 19 7 11 10 20 7 8 11 20 7 17 8 20 7 16 17 20 7 19 16 20 7 10 19 20 9 13 12 22 9 10 13 22 9 19 10 22 9 18 19 22 9 21 18 22 9 12 21 22 10 14 13 23 10 11 14 23 10 20 11 23 10 19 20 23 10 22 19 23 10 13 22 23 15 19 18 27 15 16 19 27 15 25 16 27 15 24 25 27 15 26 24 27 15 18 26 27 18 22 21 29 18 19 22 29 18 27 19 29 18 26 27 29 18 28 26 29 18 21 28 29">
      <contact solref="0.01 1" solimp="0.95 0.99 0.0001 0.5 2" selfcollide="none"/>
      <elasticity young="250" poisson="0.3"/>
      <edge damping="1"/>
    </flex>
  </deformable>
  <tendon>
    <spatial name="voxel_0_0_0_spatial_0_0_0_to_1_1_1" width="0.006" rgba="1 0 0 1" stiffness="1" damping="0">
      <site site="site_0_0_0"/>
      <site site="site_1_1_1"/>
    </spatial>
    <spatial name="voxel_0_0_0_spatial_1_1_0_to_0_0_1" width="0.006" rgba="0 1 0 1" stiffness="1" damping="0">
      <site site="site_1_1_0"/>
      <site site="site_0_0_1"/>
    </spatial>
    <spatial name="voxel_0_0_0_spatial_0_1_0_to_1_0_1" width="0.006" rgba="0 0 1 1" stiffness="1" damping="0">
      <site site="site_0_1_0"/>
      <site site="site_1_0_1"/>
    </spatial>
    <spatial name="voxel_0_0_0_spatial_1_0_0_to_0_1_1" width="0.006" rgba="1 0 1 1" stiffness="1" damping="0">
      <site site="site_1_0_0"/>
      <site site="site_0_1_1"/>
    </spatial>
    <spatial name="voxel_0_1_0_spatial_0_1_0_to_1_2_1" width="0.006" rgba="1 0 0 1" stiffness="1" damping="0">
      <site site="site_0_1_0"/>
      <site site="site_1_2_1"/>
    </spatial>
    <spatial name="voxel_0_1_0_spatial_1_2_0_to_0_1_1" width="0.006" rgba="0 1 0 1" stiffness="1" damping="0">
      <site site="site_1_2_0"/>
      <site site="site_0_1_1"/>
    </spatial>
    <spatial name="voxel_0_1_0_spatial_0_2_0_to_1_1_1" width="0.006" rgba="0 0 1 1" stiffness="1" damping="0">
      <site site="site_0_2_0"/>
      <site site="site_1_1_1"/>
    </spatial>
    <spatial name="voxel_0_1_0_spatial_1_1_0_to_0_2_1" width="0.006" rgba="1 0 1 1" stiffness="1" damping="0">
      <site site="site_1_1_0"/>
      <site site="site_0_2_1"/>
    </spatial>
    <spatial name="voxel_1_0_0_spatial_1_0_0_to_2_1_1" width="0.006" rgba="1 0 0 1" stiffness="1" damping="0">
      <site site="site_1_0_0"/>
      <site site="site_2_1_1"/>
    </spatial>
    <spatial name="voxel_1_0_0_spatial_2_1_0_to_1_0_1" width="0.006" rgba="0 1 0 1" stiffness="1" damping="0">
      <site site="site_2_1_0"/>
      <site site="site_1_0_1"/>
    </spatial>
    <spatial name="voxel_1_0_0_spatial_1_1_0_to_2_0_1" width="0.006" rgba="0 0 1 1" stiffness="1" damping="0">
      <site site="site_1_1_0"/>
      <site site="site_2_0_1"/>
    </spatial>
    <spatial name="voxel_1_0_0_spatial_2_0_0_to_1_1_1" width="0.006" rgba="1 0 1 1" stiffness="1" damping="0">
      <site site="site_2_0_0"/>
      <site site="site_1_1_1"/>
    </spatial>
    <spatial name="voxel_1_0_1_spatial_1_0_1_to_2_1_2" width="0.006" rgba="1 0 0 1" stiffness="1" damping="0">
      <site site="site_1_0_1"/>
      <site site="site_2_1_2"/>
    </spatial>
    <spatial name="voxel_1_0_1_spatial_2_1_1_to_1_0_2" width="0.006" rgba="0 1 0 1" stiffness="1" damping="0">
      <site site="site_2_1_1"/>
      <site site="site_1_0_2"/>
    </spatial>
    <spatial name="voxel_1_0_1_spatial_1_1_1_to_2_0_2" width="0.006" rgba="0 0 1 1" stiffness="1" damping="0">
      <site site="site_1_1_1"/>
      <site site="site_2_0_2"/>
    </spatial>
    <spatial name="voxel_1_0_1_spatial_2_0_1_to_1_1_2" width="0.006" rgba="1 0 1 1" stiffness="1" damping="0">
      <site site="site_2_0_1"/>
      <site site="site_1_1_2"/>
    </spatial>
    <spatial name="voxel_1_1_0_spatial_1_1_0_to_2_2_1" width="0.006" rgba="1 0 0 1" stiffness="1" damping="0">
      <site site="site_1_1_0"/>
      <site site="site_2_2_1"/>
    </spatial>
    <spatial name="voxel_1_1_0_spatial_2_2_0_to_1_1_1" width="0.006" rgba="0 1 0 1" stiffness="1" damping="0">
      <site site="site_2_2_0"/>
      <site site="site_1_1_1"/>
    </spatial>
    <spatial name="voxel_1_1_0_spatial_1_2_0_to_2_1_1" width="0.006" rgba="0 0 1 1" stiffness="1" damping="0">
      <site site="site_1_2_0"/>
      <site site="site_2_1_1"/>
    </spatial>
    <spatial name="voxel_1_1_0_spatial_2_1_0_to_1_2_1" width="0.006" rgba="1 0 1 1" stiffness="1" damping="0">
      <site site="site_2_1_0"/>
      <site site="site_1_2_1"/>
    </spatial>
    <spatial name="voxel_1_1_1_spatial_1_1_1_to_2_2_2" width="0.006" rgba="1 0 0 1" stiffness="1" damping="0">
      <site site="site_1_1_1"/>
      <site site="site_2_2_2"/>
    </spatial>
    <spatial name="voxel_1_1_1_spatial_2_2_1_to_1_1_2" width="0.006" rgba="0 1 0 1" stiffness="1" damping="0">
      <site site="site_2_2_1"/>
      <site site="site_1_1_2"/>
    </spatial>
    <spatial name="voxel_1_1_1_spatial_1_2_1_to_2_1_2" width="0.006" rgba="0 0 1 1" stiffness="1" damping="0">
      <site site="site_1_2_1"/>
      <site site="site_2_1_2"/>
    </spatial>
    <spatial name="voxel_1_1_1_spatial_2_1_1_to_1_2_2" width="0.006" rgba="1 0 1 1" stiffness="1" damping="0">
      <site site="site_2_1_1"/>
      <site site="site_1_2_2"/>
    </spatial>
    <spatial name="voxel_2_0_0_spatial_2_0_0_to_3_1_1" width="0.006" rgba="1 0 0 1" stiffness="1" damping="0">
      <site site="site_2_0_0"/>
      <site site="site_3_1_1"/>
    </spatial>
    <spatial name="voxel_2_0_0_spatial_3_1_0_to_2_0_1" width="0.006" rgba="0 1 0 1" stiffness="1" damping="0">
      <site site="site_3_1_0"/>
      <site site="site_2_0_1"/>
    </spatial>
    <spatial name="voxel_2_0_0_spatial_2_1_0_to_3_0_1" width="0.006" rgba="0 0 1 1" stiffness="1" damping="0">
      <site site="site_2_1_0"/>
      <site site="site_3_0_1"/>
    </spatial>
    <spatial name="voxel_2_0_0_spatial_3_0_0_to_2_1_1" width="0.006" rgba="1 0 1 1" stiffness="1" damping="0">
      <site site="site_3_0_0"/>
      <site site="site_2_1_1"/>
    </spatial>
    <spatial name="voxel_2_1_0_spatial_2_1_0_to_3_2_1" width="0.006" rgba="1 0 0 1" stiffness="1" damping="0">
      <site site="site_2_1_0"/>
      <site site="site_3_2_1"/>
    </spatial>
    <spatial name="voxel_2_1_0_spatial_3_2_0_to_2_1_1" width="0.006" rgba="0 1 0 1" stiffness="1" damping="0">
      <site site="site_3_2_0"/>
      <site site="site_2_1_1"/>
    </spatial>
    <spatial name="voxel_2_1_0_spatial_2_2_0_to_3_1_1" width="0.006" rgba="0 0 1 1" stiffness="1" damping="0">
      <site site="site_2_2_0"/>
      <site site="site_3_1_1"/>
    </spatial>
    <spatial name="voxel_2_1_0_spatial_3_1_0_to_2_2_1" width="0.006" rgba="1 0 1 1" stiffness="1" damping="0">
      <site site="site_3_1_0"/>
      <site site="site_2_2_1"/>
    </spatial>
  </tendon>
  <actuator>
    <motor name="voxel_0_0_0_motor_0_0_0_to_1_1_1" tendon="voxel_0_0_0_spatial_0_0_0_to_1_1_1" ctrlrange="0 1" gear="100.0"/>
    <motor name="voxel_0_0_0_motor_1_1_0_to_0_0_1" tendon="voxel_0_0_0_spatial_1_1_0_to_0_0_1" ctrlrange="0 1" gear="100.0"/>
    <motor name="voxel_0_0_0_motor_0_1_0_to_1_0_1" tendon="voxel_0_0_0_spatial_0_1_0_to_1_0_1" ctrlrange="0 1" gear="100.0"/>
    <motor name="voxel_0_0_0_motor_1_0_0_to_0_1_1" tendon="voxel_0_0_0_spatial_1_0_0_to_0_1_1" ctrlrange="0 1" gear="100.0"/>
    <motor name="voxel_0_1_0_motor_0_1_0_to_1_2_1" tendon="voxel_0_1_0_spatial_0_1_0_to_1_2_1" ctrlrange="0 1" gear="100.0"/>
    <motor name="voxel_0_1_0_motor_1_2_0_to_0_1_1" tendon="voxel_0_1_0_spatial_1_2_0_to_0_1_1" ctrlrange="0 1" gear="100.0"/>
    <motor name="voxel_0_1_0_motor_0_2_0_to_1_1_1" tendon="voxel_0_1_0_spatial_0_2_0_to_1_1_1" ctrlrange="0 1" gear="100.0"/>
    <motor name="voxel_0_1_0_motor_1_1_0_to_0_2_1" tendon="voxel_0_1_0_spatial_1_1_0_to_0_2_1" ctrlrange="0 1" gear="100.0"/>
    <motor name="voxel_1_0_0_motor_1_0_0_to_2_1_1" tendon="voxel_1_0_0_spatial_1_0_0_to_2_1_1" ctrlrange="0 1" gear="100.0"/>
    <motor name="voxel_1_0_0_motor_2_1_0_to_1_0_1" tendon="voxel_1_0_0_spatial_2_1_0_to_1_0_1" ctrlrange="0 1" gear="100.0"/>
    <motor name="voxel_1_0_0_motor_1_1_0_to_2_0_1" tendon="voxel_1_0_0_spatial_1_1_0_to_2_0_1" ctrlrange="0 1" gear="100.0"/>
    <motor name="voxel_1_0_0_motor_2_0_0_to_1_1_1" tendon="voxel_1_0_0_spatial_2_0_0_to_1_1_1" ctrlrange="0 1" gear="100.0"/>
    <motor name="voxel_1_0_1_motor_1_0_1_to_2_1_2" tendon="voxel_1_0_1_spatial_1_0_1_to_2_1_2" ctrlrange="0 1" gear="100.0"/>
    <motor name="voxel_1_0_1_motor_2_1_1_to_1_0_2" tendon="voxel_1_0_1_spatial_2_1_1_to_1_0_2" ctrlrange="0 1" gear="100.0"/>
    <motor name="voxel_1_0_1_motor_1_1_1_to_2_0_2" tendon="voxel_1_0_1_spatial_1_1_1_to_2_0_2" ctrlrange="0 1" gear="100.0"/>
    <motor name="voxel_1_0_1_motor_2_0_1_to_1_1_2" tendon="voxel_1_0_1_spatial_2_0_1_to_1_1_2" ctrlrange="0 1" gear="100.0"/>
    <motor name="voxel_1_1_0_motor_1_1_0_to_2_2_1" tendon="voxel_1_1_0_spatial_1_1_0_to_2_2_1" ctrlrange="0 1" gear="100.0"/>
    <motor name="voxel_1_1_0_motor_2_2_0_to_1_1_1" tendon="voxel_1_1_0_spatial_2_2_0_to_1_1_1" ctrlrange="0 1" gear="100.0"/>
    <motor name="voxel_1_1_0_motor_1_2_0_to_2_1_1" tendon="voxel_1_1_0_spatial_1_2_0_to_2_1_1" ctrlrange="0 1" gear="100.0"/>
    <motor name="voxel_1_1_0_motor_2_1_0_to_1_2_1" tendon="voxel_1_1_0_spatial_2_1_0_to_1_2_1" ctrlrange="0 1" gear="100.0"/>
    <motor name="voxel_1_1_1_motor_1_1_1_to_2_2_2" tendon="voxel_1_1_1_spatial_1_1_1_to_2_2_2" ctrlrange="0 1" gear="100.0"/>
    <motor name="voxel_1_1_1_motor_2_2_1_to_1_1_2" tendon="voxel_1_1_1_spatial_2_2_1_to_1_1_2" ctrlrange="0 1" gear="100.0"/>
    <motor name="voxel_1_1_1_motor_1_2_1_to_2_1_2" tendon="voxel_1_1_1_spatial_1_2_1_to_2_1_2" ctrlrange="0 1" gear="100.0"/>
    <motor name="voxel_1_1_1_motor_2_1_1_to_1_2_2" tendon="voxel_1_1_1_spatial_2_1_1_to_1_2_2" ctrlrange="0 1" gear="100.0"/>
    <motor name="voxel_2_0_0_motor_2_0_0_to_3_1_1" tendon="voxel_2_0_0_spatial_2_0_0_to_3_1_1" ctrlrange="0 1" gear="100.0"/>
    <motor name="voxel_2_0_0_motor_3_1_0_to_2_0_1" tendon="voxel_2_0_0_spatial_3_1_0_to_2_0_1" ctrlrange="0 1" gear="100.0"/>
    <motor name="voxel_2_0_0_motor_2_1_0_to_3_0_1" tendon="voxel_2_0_0_spatial_2_1_0_to_3_0_1" ctrlrange="0 1" gear="100.0"/>
    <motor name="voxel_2_0_0_motor_3_0_0_to_2_1_1" tendon="voxel_2_0_0_spatial_3_0_0_to_2_1_1" ctrlrange="0 1" gear="100.0"/>
    <motor name="voxel_2_1_0_motor_2_1_0_to_3_2_1" tendon="voxel_2_1_0_spatial_2_1_0_to_3_2_1" ctrlrange="0 1" gear="100.0"/>
    <motor name="voxel_2_1_0_motor_3_2_0_to_2_1_1" tendon="voxel_2_1_0_spatial_3_2_0_to_2_1_1" ctrlrange="0 1" gear="100.0"/>
    <motor name="voxel_2_1_0_motor_2_2_0_to_3_1_1" tendon="voxel_2_1_0_spatial_2_2_0_to_3_1_1" ctrlrange="0 1" gear="100.0"/>
    <motor name="voxel_2_1_0_motor_3_1_0_to_2_2_1" tendon="voxel_2_1_0_spatial_3_1_0_to_2_2_1" ctrlrange="0 1" gear="100.0"/>
  </actuator>
</mujoco>